Workbook
Name WBSLINK_GOVERNED_RECORDS: 'MASTER DATA'!$A$1:$W$1624

Sheet 01 PROJECT
A2: ZP SYNERGY GROUP INC.
A4: WBS↔LINK™
A5: Premium Integrated Project Controls Workbook
A7: HarbourLink Urban Transit Expansion
A10: Workbook state | B10: Approved project-controls relationship state
A11: Reporting / data date | B11: 2027-06-30 (Contractor Programme Rev 0); 2027-06-30 (Cost & Forecast Control Accounts Rev 0); 2027-06-30 (Commercial Package Register Rev 0)
A12: Approved by | B12: Maya Chen, Owner Project Controls
A13: Approved (UTC) | B13: 2026-10-12 14:25
A14: WBS version | B14: 1
A15: Source set | B15: Commercial Package Register (WORK_PACKAGE_LIST, Rev 0); Contractor Programme (SCHEDULE, Rev 0); Cost & Forecast Control Accounts (COST_ESTIMATE, Rev 0); Owner WBS (WBS_DICTIONARY, Rev 0)
A18: HarbourLink is a fictional infrastructure example. Begin with the approved position, choose one finding, then follow the original source and recorded professional authority. Use the report Print PDF for the executive print route; this workbook is the deeper working evidence tool.
A22: Begin with 02 START HERE →

Sheet 02 START HERE
A1: HOW TO USE THIS WORKBOOK
A2: Choose your task. Follow the same finding from the approved position to original evidence.
A3: Executive | B3: Issues | C3: Integration | D3: Project | E3: Changes | F3: Crosswalk | G3: Evidence | H3: Sources
A5: Start with your task | B5: Purpose and next step
A6: Executive | Position | B6: Read the approved position; four governed charts and their source tables.
A7: Controls | Issues | B7: Choose one issue and its exact professional Action. Issues are not ranked.
A8: Controls | WBS scope | B8: Primary WBS view: governed relationship coverage/status. Then open Crosswalk.
A9: Analyst | Crosswalk | B9: Filter WBS code / Source Record ID; follow the stable Relationship ID.
A10: Analyst | Evidence | B10: Match Relationship ID: source assertion, interpretation, contrary evidence, human decision.
A11: Controls | Cycle change | B11: Inspect the approved-cycle movement and what returned for review.
A12: Assurance | Sources | B12: Identify source, approved revision and original representation.
A13: Assurance | Withholding | B13: Check withholding, approved basis and definitions.
A17: One evidence path
A18: Approved position → named finding → Owner WBS → Crosswalk → original source / interpretation → professional decision → separate approval. Compare the next cycle only after reading the approved baseline.
A22: Supporting diagnostics and scope detail
A23: 13 REVISIONS & PERIODS | B23: See which reporting revision each source is on, what superseded what, and why only part of the relationship state reopened.
A24: 14 WBS HIERARCHY | B24: Approved scope tree and direct/branch relationship ROW counts. Split targets may create multiple rows; retired rows are included unless filtered. Not interchangeable with 09 WBS EXPLORER.
A25: 15 ANALYSIS | B25: Cross-tabulate governed dimensions from MASTER DATA (formulas, self-checking).
A28: EXECUTIVE | B28: Start at 03 EXECUTIVE VIEW. Read the position, exact Actions and withholding; inspect the four figures when a question needs diagnosis.
A29: PROJECT CONTROLS | B29: Start at 04 ISSUES FOR REVIEW. Choose a finding, open its WBS scope in 09, then follow the actual source record and stable Relationship ID.
A30: EVIDENCE | B30: Start at 10 EVIDENCE & DECISIONS. Match the stable Relationship ID to source assertion, interpretation, contrary evidence and the recorded professional decision. Check approval-time sources in 11.
A31: ASSURANCE / SOURCES | B31: Use 12 ASSURANCE for withholding and counting definitions; 13 REVISIONS & PERIODS records lineage. Approval is separate from a record-level decision.
A32: STUDENT · HARBOURLINK | B32: Start at WBS 1.5 Testing and Commissioning. Compare schedule and cost coverage; follow the issue to Crosswalk and Evidence. Inspect the recorded decision, then Cycle 2 Changes. This is a synthetic example, not an answer key.
A34: Tab groups | B34: Cognac: orientation. Navy: executive decisions. Navy veil: diagnostics. Grey: source and assurance evidence. Steel: advanced and compatibility views. Colours support the sheet names; they do not indicate risk or project health.
A35: Why the counts differ | B35: 09 WBS EXPLORER counts distinct relationship coverage/status. 14 WBS HIERARCHY counts relationship ROWS per target, including split targets and retired rows unless filtered. Current movement, issue groups and unplaced outcomes have different populations.
A37: Advanced evidence and supporting views
A38: 05 INTEGRATION HEALTH | B38: Cross-view relationship availability and gated analytical populations.
A39: 06 INTEGRATED PROJECT | B39: Supporting cross-view projections by WBS; use 09 for first scope navigation.
A40: MASTER DATA | B40: Compatibility/formula source table; one row per relationship target.
A41: OWNER WBS | B41: Approved source scope tree; original names, ancestry and evidence retained.
A42: RELATIONSHIP EXPLORER | B42: Advanced formula-based target-row explorer; 09 is the primary scope view.
A43: UNRESOLVED | B43: Supporting outcome records; uncertainty is not assessed outside scope.
A44: HISTORY | B44: Compatibility approved-version history; 13 provides revision lineage.
A45: SUMMARY | B45: Compatibility calculations; 03 is the canonical executive decision surface.
A50: All-sheet purpose index | B50: Role and counting population
A51: 01 PROJECT | B51: Publication identity, approved version and source-set orientation; then open the index.
A52: 02 START HERE | B52: Primary task index and discoverable supporting/advanced destinations.
A53: 03 EXECUTIVE VIEW | B53: Canonical executive decision surface and four retained native charts.
... A71: SUMMARY | B71: Compatibility calculations; 03 is the canonical executive decision surface.

Sheet 03 EXECUTIVE VIEW
A1: EXECUTIVE VIEW
A2: HarbourLink Urban Transit Expansion · approved integrated project view
A3: Executive | C3: Issues | E3: Integration | G3: Project
A4: Changes | C4: Crosswalk | E4: Evidence | G4: Sources
A5: WHERE THE PROJECT STANDS | E5: ISSUES AND WITHHOLDING
A6: 4 / 6 Owner-WBS branches schedule AND cost present | E6: 1. 1.5 Testing and Commissioning: Schedule without cost coverage. 2. 1.6 Program Management: Cost without schedule coverage. 3. 1 item is recorded outside the current Owner WBS · Outside the current Owner WBS 4. 263 items still need more information before they can be placed in the Owner WBS
A8: 1.1 Guideway and Civil Schedule: Present · Cost: Present 1.2 Stations Schedule: Present · Cost: Present 1.3 Systems Schedule: Present · Cost: Present 1.4 Vehicles and Depot Schedule: Present · Cost: Present 1.5 Testing and Commissioning Schedule: Present · Cost: ABSENT 1.6 Program Management Schedule: ABSENT · Cost: Present
E9: Cost / forecast total: Withheld. Aggregation eligibility is not established. See 12 ASSURANCE.
A10: Next step: Confirm whether the missing governed relationship is expected or requires project-controls attention. (4 issues on sheet 04.)
A11: Issues for review | C11: Initial relationships | E11: Reopened this cycle | G11: Source integrity
A12: 4 | C12: 1622 | E12: 0 | G12: Established
A13: Listed on sheet 04 | C13: Established in the current reporting baseline | E13: Event count in the current baseline; issues needing attention now are on sheet 04 | G13: Upstream truth gate
A15: Review the issues → | C15: Open Integration Health → | E15: Open Changes → | G15: Prove it in Crosswalk →
A18: What this workbook cannot establish
A19: • Amount/date/duration management measures are withheld unless their field semantics are explicitly governed for that use.
A21: 1 · Schedule and cost relationships by WBS branch | E21: 2 · Relationship outcomes by source
A23: 4 of 6 WBS branches carry both schedule and cost relationships; 2 branches are covered by only one of them. | E23: 1,357 of 1,622 current relationships relate a source record to a WBS element, across 3 source documents. 265 are recorded outside the WBS or left unresolved.
A26: Out of 6 reported WBS branches. Coverage is observed through the WBS; it is not a direct schedule-to-cost link. Detail: 05 INTEGRATION HEALTH. | E26: Out of 1,622 current relationships (retired relationships excluded); one relationship counted once even when split across several WBS elements. Detail: 08 CROSSWALK.
A51: 3 · No previous approved version to compare | E51: 4 · Outcomes left unresolved or outside the WBS
A53: No previous approved version is recorded, so all 1,622 relationships are new in this reporting baseline. The next cycle will show what carried forward and what changed. | E53: 265 of 1,622 current relationships are left unresolved or recorded outside the approved WBS. Rely only on conclusions that do not depend on them; sheet 04 groups them into the issues for review.
A56: Out of 1,622 relationships in this baseline, by change label. Detail: 07 CHANGES & REVALIDATION. | E56: Out of 1,622 current relationships (retired excluded). These are recorded, governed outcomes, not errors. Detail: sheet 04 (issues for review) and 08 CROSSWALK.
A83: FOUR VIEWS OF THE APPROVED PROJECT
A84: Each chart draws on the approved relationship records. It states what it counts, the population covered and the source table beneath it.
A86: 1 · Schedule and cost relationships by WBS branch
A87: 4 of 6 WBS branches carry both schedule and cost relationships; 2 branches are covered by only one of them.
A88: Out of 6 reported WBS branches. Coverage is observed through the WBS; it is not a direct schedule-to-cost link. Detail: 05 INTEGRATION HEALTH.
A104: WBS branches | C104: Count
A105: Schedule and cost | C105: 4
A106: Schedule only | C106: 1
A107: Cost only | C107: 1
A108: Neither schedule nor cost | C108: 0
A109: Total WBS branches | C109: 6
A111: 2 · Relationship outcomes by source
A112: 1,357 of 1,622 current relationships relate a source record to a WBS element, across 3 source documents. 265 are recorded outside the WBS or left unresolved.
A113: Out of 1,622 current relationships (retired relationships excluded); one relationship counted once even when split across several WBS elements. Detail: 08 CROSSWALK.
A129: Source document | C129: Related to a WBS element | E129: Recorded outside the WBS | G129: Left unresolved | I129: Total
A130: Commercial Package Register | C130: 60 | E130: 0 | G130: 0 | I130: 60
A131: Contractor Programme | C131: 898 | E131: 2 | G131: 182 | I131: 1082
A132: Cost & Forecast Control Accounts | C132: 399 | E132: 0 | G132: 81 | I132: 480
A133: All sources | C133: 1357 | E133: 2 | G133: 263 | I133: 1622
...

Sheet 04 ISSUES FOR REVIEW
A1: ISSUES FOR REVIEW
A2: The issues the governed evidence supports raising with the project team now. Grouped by type and WBS code; not ranked by importance.
A3: Executive | B3: Issues | C3: Integration | D3: Project | E3: Changes | F3: Crosswalk | G3: Evidence | H3: Sources
A5: Matter | B5: Why it matters | C5: Affected WBS scope | D5: Affected source view(s) | E5: State | F5: Recommended professional action | G5: Evidence path | H5: Authority
A6: Schedule scope has no governed cost relationships | B6: The supplied schedule and cost views do not both project through this approved WBS branch. | C6: 1.5 Testing and Commissioning | D6: Schedule + Cost | E6: Derived observation from governed relationships | F6: Confirm whether the missing governed relationship is expected or requires project-controls attention. | G6: 05 INTEGRATION HEALTH / 08 CROSSWALK: WBS 1.5 | H6: Derived observation; no direct schedule↔cost relationship asserted
A7: Cost scope has no governed schedule relationships | B7: The supplied schedule and cost views do not both project through this approved WBS branch. | C7: 1.6 Program Management | D7: Schedule + Cost | E7: Derived observation from governed relationships | F7: Confirm whether the missing governed relationship is expected or requires project-controls attention. | G7: 05 INTEGRATION HEALTH / 08 CROSSWALK: WBS 1.6 | H7: Derived observation; no direct schedule↔cost relationship asserted
A8: 1 governed relationship outcome(s) record NEW_SCOPE | B8: The approved relationship state records scope not represented by the current approved WBS. | C8: Outside current approved WBS | D8: See Crosswalk | E8: Professional/governed outcome | F8: Review the governed NEW_SCOPE outcomes in the project-controls context. | G8: 08 CROSSWALK: filter Relationship Type = NEW_SCOPE | H8: Governed relationship outcome
A9: 263 relationship outcome(s) remain deliberately unresolved | B9: The approved state preserves uncertainty rather than forcing a WBS relationship. | C9: See Crosswalk | D9: See Crosswalk | E9: Professionally/governed unresolved outcome | F9: Use only conclusions that do not depend on these unresolved relationships. | G9: 08 CROSSWALK / 10 EVIDENCE & DECISIONS | H9: Governed uncertainty
A11: Ordering note: matters are grouped deterministically by governed matter class and WBS code. No claim of objective project materiality or #1 priority is made.

Sheet 05 INTEGRATION HEALTH
A1: INTEGRATION HEALTH
A2: WBS branch view of governed project-control relationships. No single aggregate health percentage is asserted.
A3: Executive | B3: Issues | C3: Integration | D3: Project | E3: Changes | F3: Crosswalk | G3: Evidence | H3: Sources | K3: V2 · WHERE PROFESSIONAL ATTENTION IS CONCENTRATED
K4: Where are governed reopened, unresolved or contradictory relationship populations concentrated?
A5: WBS | B5: Scope | C5: Schedule | D5: Cost / forecast | E5: Package / contract | F5: Integration condition | G5: Attention / unresolved | H5: Changed | I5: Evidence path | K5: WBS | L5: Reopened | M5: Unresolved | N5: Contradictory | O5: Attention records
A6: 1.1 | B6: Guideway and Civil | C6: 180 governed relationships | D6: 80 governed relationships | E6: 10 governed relationships | F6: Aligned: Schedule and cost both relate through this WBS branch. 10 package/contract relationships also project through this branch. | G6: 0 | H6: 270 | I6: 06 INTEGRATED PROJECT / 08 CROSSWALK: WBS 1.1 | K6: 1.1 | L6: 0 | M6: 0 | N6: 1 | O6: 1
A7: 1.2 | B7: Stations | C7: 179 governed relationships | D7: 80 governed relationships | E7: 11 governed relationships | F7: Aligned: Schedule and cost both relate through this WBS branch. 11 package/contract relationships also project through this branch. | G7: 0 | H7: 270 | I7: 06 INTEGRATED PROJECT / 08 CROSSWALK: WBS 1.2 | K7: 1.2 | L7: 0 | M7: 0 | N7: 1 | O7: 1
A8: 1.3 | B8: Systems | C8: 180 governed relationships | D8: 79 governed relationships | E8: 10 governed relationships | F8: Aligned: Schedule and cost both relate through this WBS branch. 10 package/contract relationships also project through this branch. | G8: 0 | H8: 269 | I8: 06 INTEGRATED PROJECT / 08 CROSSWALK: WBS 1.3 | K8: 1.3 | L8: 0 | M8: 0 | N8: 0 | O8: 0
A9: 1.4 | B9: Vehicles and Depot | C9: 179 governed relationships | D9: 80 governed relationships | E9: 10 governed relationships | F9: Aligned: Schedule and cost both relate through this WBS branch. 10 package/contract relationships also project through this branch. | G9: 0 | H9: 269 | I9: 06 INTEGRATED PROJECT / 08 CROSSWALK: WBS 1.4 | K9: 1.4 | L9: 0 | M9: 0 | N9: 0 | O9: 0
A10: 1.5 | B10: Testing and Commissioning | C10: 180 governed relationships | D10: 0 governed relationships | E10: 10 governed relationships | F10: Attention: Schedule scope has no governed cost relationships in this WBS branch. 10 package/contract relationships also project through this branch. | G10: 0 | H10: 190 | I10: 06 INTEGRATED PROJECT / 08 CROSSWALK: WBS 1.5 | K10: 1.5 | L10: 0 | M10: 0 | N10: 0 | O10: 0
A11: 1.6 | B11: Program Management | C11: 0 governed relationships | D11: 80 governed relationships | E11: 10 governed relationships | F11: Attention: Cost scope has no governed schedule relationships in this WBS branch. 10 package/contract relationships also project through this branch. | G11: 0 | H11: 90 | I11: 06 INTEGRATED PROJECT / 08 CROSSWALK: WBS 1.6 | K11: 1.6 | L11: 0 | M11: 0 | N11: 0 | O11: 0
K12: Counts locate governed professional-attention populations only; they are not financial or schedule materiality rankings.
B13: V1 · WBS × CONTROL-VIEW INTEGRATION MATRIX
B14: Which supplied project-control views have governed relationships through each major Owner-WBS branch?
B16: WBS | C16: Scope | D16: Schedule | E16: Cost / forecast | F16: Package / contract | G16: Responsibility | H16: Proof path
B17: 1.1 | C17: Guideway and Civil | D17: 180 governed relationships | E17: 80 governed relationships | F17: 10 governed relationships | G17: Not supplied | H17: 06 INTEGRATED PROJECT / 08 CROSSWALK: WBS 1.1
B18: 1.2 | C18: Stations | D18: 179 governed relationships | E18: 80 governed relationships | F18: 11 governed relationships | G18: Not supplied | H18: 06 INTEGRATED PROJECT / 08 CROSSWALK: WBS 1.2
B19: 1.3 | C19: Systems | D19: 180 governed relationships | E19: 79 governed relationships | F19: 10 governed relationships | G19: Not supplied | H19: 06 INTEGRATED PROJECT / 08 CROSSWALK: WBS 1.3
B20: 1.4 | C20: Vehicles and Depot | D20: 179 governed relationships | E20: 80 governed relationships | F20: 10 governed relationships | G20: Not supplied | H20: 06 INTEGRATED PROJECT / 08 CROSSWALK: WBS 1.4
B21: 1.5 | C21: Testing and Commissioning | D21: 180 governed relationships | E21: Assessed · no governed coverage | F21: 10 governed relationships | G21: Not supplied | H21: 06 INTEGRATED PROJECT / 08 CROSSWALK: WBS 1.5
B22: 1.6 | C22: Program Management | D22: Assessed · no governed coverage | E22: 80 governed relationships | F22: 10 governed relationships | G22: Not supplied | H22: 06 INTEGRATED PROJECT / 08 CROSSWALK: WBS 1.6
B23: Unresolved is distinct from assessed zero coverage and source-not-supplied.
A25: V4 · COST / FORECAST VISUAL WITHHELD
A26: Withheld: current generic field-name recognition is not a governed quantitative contract. Measure meaning, currency/unit, period, grain, WBS basis, allocation and unresolved treatment must all be established.

Sheet 06 INTEGRATED PROJECT
A1: INTEGRATED PROJECT
A2: Working projection of independently authored project views through the approved WBS integration spine.
A3: Executive | B3: Issues | C3: Integration | D3: Project | E3: Changes | F3: Crosswalk | G3: Evidence | H3: Sources
A5: WBS | B5: Scope | C5: Schedule relationships | D5: Cost relationships | E5: Package / contract relationships | F5: Other relationships | G5: Open / unresolved | H5: Changed | I5: Current integration observation | J5: Drill to proof
B6: HarbourLink Urban Transit Expansion | C6: 898 governed relationships | D6: 399 governed relationships | E6: 60 governed relationships | F6: 0 governed relationships | G6: 0 | H6: 1357 | I6: Schedule and cost both relate through this WBS branch. 60 package/contract relationships also project through this branch. | J6: 08 CROSSWALK: WBS
A7: 1 | B7: HarbourLink Urban Transit Expansion | C7: 898 governed relationships | D7: 399 governed relationships | E7: 60 governed relationships | F7: 0 governed relationships | G7: 0 | H7: 1357 | I7: Schedule and cost both relate through this WBS branch. 60 package/contract relationships also project through this branch. | J7: 08 CROSSWALK: WBS 1
A8: 1.1 | B8: Guideway and Civil | C8: 180 governed relationships | D8: 80 governed relationships | E8: 10 governed relationships | F8: 0 governed relationships | G8: 0 | H8: 270 | I8: Schedule and cost both relate through this WBS branch. 10 package/contract relationships also project through this branch. | J8: 08 CROSSWALK: WBS 1.1
A9: 1.1.1 | B9: Guideway and Civil - Guideway Structures | C9: 120 governed relationships | D9: 40 governed relationships | E9: 0 governed relationships | F9: 0 governed relationships | G9: 0 | H9: 160 | I9: Schedule and cost both relate through this WBS branch. | J9: 08 CROSSWALK: WBS 1.1.1
A10: 1.1.1.1 | B10: Guideway Structures - East Segment | C10: 0 governed relationships | D10: 0 governed relationships | E10: 0 governed relationships | F10: 0 governed relationships | G10: 0 | H10: 0 | I10: No governed schedule or cost relationships in this WBS branch. | J10: 08 CROSSWALK: WBS 1.1.1.1
A11: 1.1.1.2 | B11: Guideway Structures - West Segment | C11: 0 governed relationships | D11: 0 governed relationships | E11: 0 governed relationships | F11: 0 governed relationships | G11: 0 | H11: 0 | I11: No governed schedule or cost relationships in this WBS branch. | J11: 08 CROSSWALK: WBS 1.1.1.2
A12: 1.1.2 | B12: Guideway and Civil - Utility & Roadworks | C12: 60 governed relationships | D12: 40 governed relationships | E12: 0 governed relationships | F12: 0 governed relationships | G12: 0 | H12: 100 | I12: Schedule and cost both relate through this WBS branch. | J12: 08 CROSSWALK: WBS 1.1.2
A13: 1.1.2.1 | B13: Utility & Roadworks - East Segment | C13: 0 governed relationships | D13: 0 governed relationships | E13: 0 governed relationships | F13: 0 governed relationships | G13: 0 | H13: 0 | I13: No governed schedule or cost relationships in this WBS branch. | J13: 08 CROSSWALK: WBS 1.1.2.1
A14: 1.1.2.2 | B14: Utility & Roadworks - West Segment | C14: 0 governed relationships | D14: 0 governed relationships | E14: 0 governed relationships | F14: 0 governed relationships | G14: 0 | H14: 0 | I14: No governed schedule or cost relationships in this WBS branch. | J14: 08 CROSSWALK: WBS 1.1.2.2
A15: 1.1.3 | B15: Guideway and Civil - Track Support Works | C15: 0 governed relationships | D15: 0 governed relationships | E15: 0 governed relationships | F15: 0 governed relationships | G15: 0 | H15: 0 | I15: No governed schedule or cost relationships in this WBS branch. | J15: 08 CROSSWALK: WBS 1.1.3
A16: 1.1.3.1 | B16: Track Support Works - East Segment | C16: 0 governed relationships | D16: 0 governed relationships | E16: 0 governed relationships | F16: 0 governed relationships | G16: 0 | H16: 0 | I16: No governed schedule or cost relationships in this WBS branch. | J16: 08 CROSSWALK: WBS 1.1.3.1
A17: 1.1.3.2 | B17: Track Support Works - West Segment | C17: 0 governed relationships | D17: 0 governed relationships | E17: 0 governed relationships | F17: 0 governed relationships | G17: 0 | H17: 0 | I17: No governed schedule or cost relationships in this WBS branch. | J17: 08 CROSSWALK: WBS 1.1.3.2
A18: 1.1.4 | B18: Guideway and Civil - Civil Interfaces | C18: 0 governed relationships | D18: 0 governed relationships | E18: 0 governed relationships | F18: 0 governed relationships | G18: 0 | H18: 0 | I18: No governed schedule or cost relationships in this WBS branch. | J18: 08 CROSSWALK: WBS 1.1.4
... A85: 1.6.4.2 | B85: Delivery Integration - Delivery Partners | C85: 0 governed relationships | D85: 0 governed relationships | E85: 0 governed relationships | F85: 0 governed relationships | G85: 0 | H85: 0 | I85: No governed schedule or cost relationships in this WBS branch. | J85: 08 CROSSWALK: WBS 1.6.4.2

Sheet 07 CHANGES & REVALIDATION
A1: CHANGES & REVALIDATION
A2: What changed that matters, what remained valid, and where revalidation occurred.
A3: Executive | B3: Issues | C3: Integration | D3: Project | E3: Changes | F3: Crosswalk | G3: Evidence | H3: Sources
A5: Initial approved relationship state · current reporting baseline | D5: V3 · CYCLE CONTINUITY
A6: Carried forward | B6: 0 | D6: This is the initial approved relationship baseline; the counts at left describe the current governed state.
A7: Re-keyed, revalidated | B7: 0
A8: Changed, re-decided | B8: 0
A9: New | B9: 1622 | D9: All relationships shown as New were established in this initial baseline; they are not changes from a prior approved cycle.
A10: Retired | B10: 0
A12: Relationship | B12: Source | C12: Record | D12: WBS | E12: Change state | F12: Reopen / revalidation reason | G12: Decision provenance | H12: Evidence path
A13: R1563-v2 | B13: Commercial Package Register | C13: PKG-001 | D13: 1.1 Guideway and Civil | E13: New | G13: Maya Chen, Owner Project Controls | H13: 10 EVIDENCE & DECISIONS
A14: R1564-v1 | B14: Commercial Package Register | C14: PKG-002 | D14: 1.1 Guideway and Civil | E14: New | G14: Source assignment -- not individually reviewed | H14: 10 EVIDENCE & DECISIONS
A15: R1565-v1 | B15: Commercial Package Register | C15: PKG-003 | D15: 1.1 Guideway and Civil | E15: New | G15: Source assignment -- not individually reviewed | H15: 10 EVIDENCE & DECISIONS
A16: R1566-v1 | B16: Commercial Package Register | C16: PKG-004 | D16: 1.1 Guideway and Civil | E16: New | G16: Source assignment -- not individually reviewed | H16: 10 EVIDENCE & DECISIONS
A17: R1567-v1 | B17: Commercial Package Register | C17: PKG-005 | D17: 1.1 Guideway and Civil | E17: New | G17: Source assignment -- not individually reviewed | H17: 10 EVIDENCE & DECISIONS
A18: R1568-v1 | B18: Commercial Package Register | C18: PKG-006 | D18: 1.1 Guideway and Civil | E18: New | G18: Source assignment -- not individually reviewed | H18: 10 EVIDENCE & DECISIONS
A19: R1569-v1 | B19: Commercial Package Register | C19: PKG-007 | D19: 1.1 Guideway and Civil | E19: New | G19: Source assignment -- not individually reviewed | H19: 10 EVIDENCE & DECISIONS
A20: R1570-v1 | B20: Commercial Package Register | C20: PKG-008 | D20: 1.1 Guideway and Civil | E20: New | G20: Source assignment -- not individually reviewed | H20: 10 EVIDENCE & DECISIONS
A21: R1571-v1 | B21: Commercial Package Register | C21: PKG-009 | D21: 1.1 Guideway and Civil | E21: New | G21: Source assignment -- not individually reviewed | H21: 10 EVIDENCE & DECISIONS
A22: R1572-v1 | B22: Commercial Package Register | C22: PKG-010 | D22: 1.1 Guideway and Civil | E22: New | G22: Source assignment -- not individually reviewed | H22: 10 EVIDENCE & DECISIONS
A23: R1-v1 | B23: Contractor Programme | C23: SCH-01-001 | D23: 1.1.1 Guideway and Civil - Guideway Structures | E23: New | G23: Source assignment -- not individually reviewed | H23: 10 EVIDENCE & DECISIONS
A24: R10-v1 | B24: Contractor Programme | C24: SCH-01-010 | D24: 1.1.1 Guideway and Civil - Guideway Structures | E24: New | G24: Source assignment -- not individually reviewed | H24: 10 EVIDENCE & DECISIONS
... A1634: R999-v2 | B1634: Contractor Programme | C1634: SCH-06-099 | D1634: UNSURE | E1634: New | G1634: Maya Chen, Owner Project Controls | H1634: 10 EVIDENCE & DECISIONS

Sheet 08 CROSSWALK
A1: CROSSWALK
A2: Inspectable relationship truth: source record → governed relationship → WBS target.
A3: Executive | B3: Issues | C3: Integration | D3: Project | E3: Changes | F3: Crosswalk | G3: Evidence | H3: Sources
A5: Source | B5: Record | C5: Description | D5: Source assertion | E5: Relationship | F5: Target WBS | G5: Relationship type | H5: Lifecycle state | I5: Change | J5: Basis / origin | K5: Decided by | L5: Target status | M5: Contrary evidence | N5: Evidence & decisions
A6: Commercial Package Register | B6: PKG-001 | C6: Guideway Civil Works | D6: Package Code = PK-101; WBS Code = 1.1;1.2 | E6: R1563-v2 | F6: 1.1 Guideway and Civil | G6: ONE_TO_MANY | H6: APPROVED | I6: New | J6: Professional decision | K6: Maya Chen, Owner Project Controls | M6: Source states 'WBS Code' = '1.1;1.2' -- names no element of this WBS -- professional reason (Maya Chen, Owner Project Controls): Source package register explicitly states both Owner-WBS branches. | N6: 10 EVIDENCE & DECISIONS
A7: Commercial Package Register | B7: PKG-002 | C7: Utility Relocations | D7: Package Code = PK-102; WBS Code = 1.1 | E7: R1564-v1 | F7: 1.1 Guideway and Civil | G7: ONE_TO_ONE | H7: APPROVED | I7: New | J7: Source assignment -- not individually reviewed | N7: 10 EVIDENCE & DECISIONS
A8: Commercial Package Register | B8: PKG-003 | C8: Road & Drainage | D8: Package Code = PK-103; WBS Code = 1.1 | E8: R1565-v1 | F8: 1.1 Guideway and Civil | G8: ONE_TO_ONE | H8: APPROVED | I8: New | J8: Source assignment -- not individually reviewed | N8: 10 EVIDENCE & DECISIONS
A9: Commercial Package Register | B9: PKG-004 | C9: Track Support Works | D9: Package Code = PK-104; WBS Code = 1.1 | E9: R1566-v1 | F9: 1.1 Guideway and Civil | G9: ONE_TO_ONE | H9: APPROVED | I9: New | J9: Source assignment -- not individually reviewed | N9: 10 EVIDENCE & DECISIONS
A10: Commercial Package Register | B10: PKG-005 | C10: Guideway Civil Works - Lot 2 | D10: Package Code = PK-105; WBS Code = 1.1 | E10: R1567-v1 | F10: 1.1 Guideway and Civil | G10: ONE_TO_ONE | H10: APPROVED | I10: New | J10: Source assignment -- not individually reviewed | N10: 10 EVIDENCE & DECISIONS
A11: Commercial Package Register | B11: PKG-006 | C11: Utility Relocations - Lot 2 | D11: Package Code = PK-106; WBS Code = 1.1 | E11: R1568-v1 | F11: 1.1 Guideway and Civil | G11: ONE_TO_ONE | H11: APPROVED | I11: New | J11: Source assignment -- not individually reviewed | N11: 10 EVIDENCE & DECISIONS
A12: Commercial Package Register | B12: PKG-007 | C12: Road & Drainage - Lot 2 | D12: Package Code = PK-107; WBS Code = 1.1 | E12: R1569-v1 | F12: 1.1 Guideway and Civil | G12: ONE_TO_ONE | H12: APPROVED | I12: New | J12: Source assignment -- not individually reviewed | N12: 10 EVIDENCE & DECISIONS
A13: Commercial Package Register | B13: PKG-008 | C13: Track Support Works - Lot 2 | D13: Package Code = PK-108; WBS Code = 1.1 | E13: R1570-v1 | F13: 1.1 Guideway and Civil | G13: ONE_TO_ONE | H13: APPROVED | I13: New | J13: Source assignment -- not individually reviewed | N13: 10 EVIDENCE & DECISIONS
A14: Commercial Package Register | B14: PKG-009 | C14: Guideway Civil Works - Lot 3 | D14: Package Code = PK-109; WBS Code = 1.1 | E14: R1571-v1 | F14: 1.1 Guideway and Civil | G14: ONE_TO_ONE | H14: APPROVED | I14: New | J14: Source assignment -- not individually reviewed | N14: 10 EVIDENCE & DECISIONS
A15: Commercial Package Register | B15: PKG-010 | C15: Utility Relocations - Lot 3 | D15: Package Code = PK-110; WBS Code = 1.1 | E15: R1572-v1 | F15: 1.1 Guideway and Civil | G15: ONE_TO_ONE | H15: APPROVED | I15: New | J15: Source assignment -- not individually reviewed | N15: 10 EVIDENCE & DECISIONS
A16: Contractor Programme | B16: SCH-01-001 | C16: West approach: track-slab survey - installation | D16: WBS Code = 1.1.1 | E16: R1-v1 | F16: 1.1.1 Guideway and Civil - Guideway Structures | G16: ONE_TO_ONE | H16: APPROVED | I16: New | J16: Source assignment -- not individually reviewed | N16: 10 EVIDENCE & DECISIONS
A17: Contractor Programme | B17: SCH-01-002 | C17: Depot lead: temporary traffic staging - inspection | D17: WBS Code = 1.1.1 | E17: R2-v1 | F17: 1.1.1 Guideway and Civil - Guideway Structures | G17: ONE_TO_ONE | H17: APPROVED | I17: New | J17: Source assignment -- not individually reviewed | N17: 10 EVIDENCE & DECISIONS
A18: Contractor Programme | B18: SCH-01-004 | C18: River crossing: road restoration - release | D18: WBS Code = 1.1.1 | E18: R4-v1 | F18: 1.1.1 Guideway and Civil - Guideway Structures | G18: ONE_TO_ONE | H18: APPROVED | I18: New | J18: Source assignment -- not individually reviewed | N18: 10 EVIDENCE & DECISIONS
... A275: Cost & Forecast Control Accounts | B275: CST-01-080 | C275: Guideway and Civil - temporary works - supply and install | D275: Cost Account = CA-1080; WBS Code = 1.1.2 | E275: R1162-v1 | F275: 1.1.2 Guideway and Civil - Utility & Roadworks | G275: ONE_TO_ONE | H275: APPROVED | I275: New | J275: Source assignment -- not individually reviewed | N275: 10 EVIDENCE & DECISIONS
A276: Commercial Package Register | B276: PKG-001 | C276: Guideway Civil Works | D276: Package Code = PK-101; WBS Code = 1.1;1.2 | E276: R1563-v2 | F276: 1.2 Stations | G276: ONE_TO_MANY | H276: APPROVED | I276: New | J276: Professional decision | K276: Maya Chen, Owner Project Controls | M276: Source states 'WBS Code' = '1.1;1.2' -- names no element of this WBS -- professional reason (Maya Chen, Owner Project Controls): Source package register explicitly states both Owner-WBS branches. | N276: 10 EVIDENCE & DECISIONS
A277: Commercial Package Register | B277: PKG-011 | C277: Station Structural Works | D277: Package Code = PK-201; WBS Code = 1.2 | E277: R1573-v1 | F277: 1.2 Stations | G277: ONE_TO_ONE | H277: APPROVED | I277: New | J277: Source assignment -- not individually reviewed | N277: 10 EVIDENCE & DECISIONS
A278: Commercial Package Register | B278: PKG-012 | C278: Station Fit-Out | D278: Package Code = PK-202; WBS Code = 1.2 | E278: R1574-v1 | F278: 1.2 Stations | G278: ONE_TO_ONE | H278: APPROVED | I278: New | J278: Source assignment -- not individually reviewed | N278: 10 EVIDENCE & DECISIONS
A279: Commercial Package Register | B279: PKG-013 | C279: Building Services | D279: Package Code = PK-203; WBS Code = 1.2 | E279: R1575-v1 | F279: 1.2 Stations | G279: ONE_TO_ONE | H279: APPROVED | I279: New | J279: Source assignment -- not individually reviewed | N279: 10 EVIDENCE & DECISIONS
A280: Commercial Package Register | B280: PKG-014 | C280: Public Realm | D280: Package Code = PK-204; WBS Code = 1.2 | E280: R1576-v1 | F280: 1.2 Stations | G280: ONE_TO_ONE | H280: APPROVED | I280: New | J280: Source assignment -- not individually reviewed | N280: 10 EVIDENCE & DECISIONS
A281: Commercial Package Register | B281: PKG-015 | C281: Station Structural Works - Lot 2 | D281: Package Code = PK-205; WBS Code = 1.2 | E281: R1577-v1 | F281: 1.2 Stations | G281: ONE_TO_ONE | H281: APPROVED | I281: New | J281: Source assignment -- not individually reviewed | N281: 10 EVIDENCE & DECISIONS
A282: Commercial Package Register | B282: PKG-016 | C282: Station Fit-Out - Lot 2 | D282: Package Code = PK-206; WBS Code = 1.2 | E282: R1578-v1 | F282: 1.2 Stations | G282: ONE_TO_ONE | H282: APPROVED | I282: New | J282: Source assignment -- not individually reviewed | N282: 10 EVIDENCE & DECISIONS
A283: Commercial Package Register | B283: PKG-017 | C283: Building Services - Lot 2 | D283: Package Code = PK-207; WBS Code = 1.2 | E283: R1579-v1 | F283: 1.2 Stations | G283: ONE_TO_ONE | H283: APPROVED | I283: New | J283: Source assignment -- not individually reviewed | N283: 10 EVIDENCE & DECISIONS
A284: Commercial Package Register | B284: PKG-018 | C284: Public Realm - Lot 2 | D284: Package Code = PK-208; WBS Code = 1.2 | E284: R1580-v1 | F284: 1.2 Stations | G284: ONE_TO_ONE | H284: APPROVED | I284: New | J284: Source assignment -- not individually reviewed | N284: 10 EVIDENCE & DECISIONS
A285: Commercial Package Register | B285: PKG-019 | C285: Station Structural Works - Lot 3 | D285: Package Code = PK-209; WBS Code = 1.2 | E285: R1581-v1 | F285: 1.2 Stations | G285: ONE_TO_ONE | H285: APPROVED | I285: New | J285: Source assignment -- not individually reviewed | N285: 10 EVIDENCE & DECISIONS
A286: Commercial Package Register | B286: PKG-020 | C286: Station Fit-Out - Lot 3 | D286: Package Code = PK-210; WBS Code = 1.2 | E286: R1582-v1 | F286: 1.2 Stations | G286: ONE_TO_ONE | H286: APPROVED | I286: New | J286: Source assignment -- not individually reviewed | N286: 10 EVIDENCE & DECISIONS
A287: Contractor Programme | B287: SCH-02-001 | C287: Harbour Station: vertical-transport installation - inspection | D287: WBS Code = 1.2.1 | E287: R181-v1 | F287: 1.2.1 Stations - Station Structures | G287: ONE_TO_ONE | H287: APPROVED | I287: New | J287: Source assignment -- not individually reviewed | N287: 10 EVIDENCE & DECISIONS
A288: Contractor Programme | B288: SCH-02-002 | C288: Market Station: platform edge installation - turnover | D288: WBS Code = 1.2.1 | E288: R182-v1 | F288: 1.2.1 Stations - Station Structures | G288: ONE_TO_ONE | H288: APPROVED | I288: New | J288: Source assignment -- not individually reviewed | N288: 10 EVIDENCE & DECISIONS
... A1363: Cost & Forecast Control Accounts | B1363: CST-06-080 | C1363: Program Management - stakeholder services - supply and install | D1363: Cost Account = CA-6080; WBS Code = 1.6.2 | E1363: R1562-v1 | F1363: 1.6.2 Program Management - Commercial & Procurement | G1363: ONE_TO_ONE | H1363: APPROVED | I1363: New | J1363: Source assignment -- not individually reviewed | N1363: 10 EVIDENCE & DECISIONS
A1364: Contractor Programme | B1364: SCH-90-901 | C1364: Temporary offsite logistics compound | D1364: WBS Code = 2.1 | E1364: R1081-v2 | F1364: NEW_SCOPE | G1364: NEW_SCOPE | H1364: APPROVED | I1364: New | J1364: Professional decision | K1364: Maya Chen, Owner Project Controls | M1364: Source states 'WBS Code' = '2.1' -- names no element of this WBS -- professional reason (Maya Chen, Owner Project Controls): Source states a project-delivery code outside the currently approved Owner WBS. | N1364: 10 EVIDENCE & DECISIONS
A1365: Contractor Programme | B1365: SCH-90-902 | C1365: Corporate training unrelated to project delivery scope | E1365: R1082-v2 | F1365: NO_WBS | G1365: NO_WBS | H1365: APPROVED | I1365: New | J1365: Professional decision | K1365: Maya Chen, Owner Project Controls | N1365: 10 EVIDENCE & DECISIONS
A1366: Contractor Programme | B1366: SCH-02-003 | C1366: Interface works near stations boundary | E1366: R183-v2 | F1366: UNSURE | G1366: UNSURE | H1366: APPROVED | I1366: New | J1366: Professional decision | K1366: Maya Chen, Owner Project Controls | N1366: 10 EVIDENCE & DECISIONS
A1367: Contractor Programme | B1367: SCH-04-003 | C1367: Interface works near vehicles and depot boundary | E1367: R543-v2 | F1367: UNSURE | G1367: UNSURE | H1367: APPROVED | I1367: New | J1367: Professional decision | K1367: Maya Chen, Owner Project Controls | N1367: 10 EVIDENCE & DECISIONS
A1368: Contractor Programme | B1368: SCH-06-001 | C1368: Systems package: commercial change review - installation | E1368: R901-v2 | F1368: UNSURE | G1368: UNSURE | H1368: APPROVED | I1368: New | J1368: Professional decision | K1368: Maya Chen, Owner Project Controls | N1368: 10 EVIDENCE & DECISIONS
A1369: Contractor Programme | B1369: SCH-06-002 | C1369: Fleet package: design-package integration review - inspection | E1369: R902-v2 | F1369: UNSURE | G1369: UNSURE | H1369: APPROVED | I1369: New | J1369: Professional decision | K1369: Maya Chen, Owner Project Controls | N1369: 10 EVIDENCE & DECISIONS
A1370: Contractor Programme | B1370: SCH-06-003 | C1370: Interface works near program management boundary | E1370: R903-v2 | F1370: UNSURE | G1370: UNSURE | H1370: APPROVED | I1370: New | J1370: Professional decision | K1370: Maya Chen, Owner Project Controls | N1370: 10 EVIDENCE & DECISIONS
A1371: Contractor Programme | B1371: SCH-06-004 | C1371: Civil package: permit coordination - release | E1371: R904-v2 | F1371: UNSURE | G1371: UNSURE | H1371: APPROVED | I1371: New | J1371: Professional decision | K1371: Maya Chen, Owner Project Controls | N1371: 10 EVIDENCE & DECISIONS
...

Sheet 09 WBS EXPLORER
A1: WBS EXPLORER
A2: The approved WBS as integration spine, with governed relationship populations beneath it.
A3: Executive | B3: Issues | C3: Integration | D3: Project | E3: Changes | F3: Crosswalk | G3: Evidence | H3: Sources
A4: Governed relationship coverage/status → advanced approved scope / relationship-row view
A5: WBS | B5: Element | C5: Level | D5: Schedule | E5: Cost / forecast | F5: Package / contract | G5: Other | H5: Open / unresolved | I5: Changed | J5: Integration condition | K5: Crosswalk
B6: HarbourLink Urban Transit Expansion | C6: 0 | D6: 898 governed relationships | E6: 399 governed relationships | F6: 60 governed relationships | G6: 0 governed relationships | H6: 0 | I6: 1357 | J6: Aligned: Schedule and cost both relate through this WBS branch. 60 package/contract relationships also project through this branch. | K6: 08 CROSSWALK
A7: 1 | B7: HarbourLink Urban Transit Expansion | C7: 1 | D7: 898 governed relationships | E7: 399 governed relationships | F7: 60 governed relationships | G7: 0 governed relationships | H7: 0 | I7: 1357 | J7: Aligned: Schedule and cost both relate through this WBS branch. 60 package/contract relationships also project through this branch. | K7: 08 CROSSWALK
A8: 1.1 | B8: Guideway and Civil | C8: 2 | D8: 180 governed relationships | E8: 80 governed relationships | F8: 10 governed relationships | G8: 0 governed relationships | H8: 0 | I8: 270 | J8: Aligned: Schedule and cost both relate through this WBS branch. 10 package/contract relationships also project through this branch. | K8: 08 CROSSWALK
A9: 1.1.1 | B9: Guideway and Civil - Guideway Structures | C9: 3 | D9: 120 governed relationships | E9: 40 governed relationships | F9: 0 governed relationships | G9: 0 governed relationships | H9: 0 | I9: 160 | J9: Aligned: Schedule and cost both relate through this WBS branch. | K9: 08 CROSSWALK
A10: 1.1.1.1 | B10: Guideway Structures - East Segment | C10: 4 | D10: 0 governed relationships | E10: 0 governed relationships | F10: 0 governed relationships | G10: 0 governed relationships | H10: 0 | I10: 0 | J10: Partial: No governed schedule or cost relationships in this WBS branch. | K10: 08 CROSSWALK
A11: 1.1.1.2 | B11: Guideway Structures - West Segment | C11: 4 | D11: 0 governed relationships | E11: 0 governed relationships | F11: 0 governed relationships | G11: 0 governed relationships | H11: 0 | I11: 0 | J11: Partial: No governed schedule or cost relationships in this WBS branch. | K11: 08 CROSSWALK
A12: 1.1.2 | B12: Guideway and Civil - Utility & Roadworks | C12: 3 | D12: 60 governed relationships | E12: 40 governed relationships | F12: 0 governed relationships | G12: 0 governed relationships | H12: 0 | I12: 100 | J12: Aligned: Schedule and cost both relate through this WBS branch. | K12: 08 CROSSWALK
A13: 1.1.2.1 | B13: Utility & Roadworks - East Segment | C13: 4 | D13: 0 governed relationships | E13: 0 governed relationships | F13: 0 governed relationships | G13: 0 governed relationships | H13: 0 | I13: 0 | J13: Partial: No governed schedule or cost relationships in this WBS branch. | K13: 08 CROSSWALK
A14: 1.1.2.2 | B14: Utility & Roadworks - West Segment | C14: 4 | D14: 0 governed relationships | E14: 0 governed relationships | F14: 0 governed relationships | G14: 0 governed relationships | H14: 0 | I14: 0 | J14: Partial: No governed schedule or cost relationships in this WBS branch. | K14: 08 CROSSWALK
A15: 1.1.3 | B15: Guideway and Civil - Track Support Works | C15: 3 | D15: 0 governed relationships | E15: 0 governed relationships | F15: 0 governed relationships | G15: 0 governed relationships | H15: 0 | I15: 0 | J15: Partial: No governed schedule or cost relationships in this WBS branch. | K15: 08 CROSSWALK
A16: 1.1.3.1 | B16: Track Support Works - East Segment | C16: 4 | D16: 0 governed relationships | E16: 0 governed relationships | F16: 0 governed relationships | G16: 0 governed relationships | H16: 0 | I16: 0 | J16: Partial: No governed schedule or cost relationships in this WBS branch. | K16: 08 CROSSWALK
A17: 1.1.3.2 | B17: Track Support Works - West Segment | C17: 4 | D17: 0 governed relationships | E17: 0 governed relationships | F17: 0 governed relationships | G17: 0 governed relationships | H17: 0 | I17: 0 | J17: Partial: No governed schedule or cost relationships in this WBS branch. | K17: 08 CROSSWALK
A18: 1.1.4 | B18: Guideway and Civil - Civil Interfaces | C18: 3 | D18: 0 governed relationships | E18: 0 governed relationships | F18: 0 governed relationships | G18: 0 governed relationships | H18: 0 | I18: 0 | J18: Partial: No governed schedule or cost relationships in this WBS branch. | K18: 08 CROSSWALK
... A85: 1.6.4.2 | B85: Delivery Integration - Delivery Partners | C85: 4 | D85: 0 governed relationships | E85: 0 governed relationships | F85: 0 governed relationships | G85: 0 governed relationships | H85: 0 | I85: 0 | J85: Partial: No governed schedule or cost relationships in this WBS branch. | K85: 08 CROSSWALK

Sheet 10 EVIDENCE & DECISIONS
A1: EVIDENCE & DECISIONS
A2: Source says → relationship / interpretation → professional decision → current governed state.
A3: Executive | B3: Issues | C3: Integration | D3: Project | E3: Changes | F3: Crosswalk | G3: Evidence | H3: Sources
A5: Relationship | B5: Source / record | C5: SOURCE SAYS | D5: RELATIONSHIP / INTERPRETATION | E5: Contrary / competing evidence | F5: PROFESSIONAL DECISION | G5: Decision scope | H5: CURRENT GOVERNED STATE | I5: Change / reopen | J5: Crosswalk
A6: R1563-v2 | B6: Commercial Package Register / PKG-001 | C6: Package Code = PK-101; WBS Code = 1.1;1.2 | D6: Proposed by Professional; target 1.1 Guideway and Civil | E6: Source states 'WBS Code' = '1.1;1.2' -- names no element of this WBS -- professional reason (Maya Chen, Owner Project Controls): Source package register explicitly states both Owner-WBS branches. | F6: Maya Chen, Owner Project Controls: Professional decision | G6: Individual | H6: APPROVED / ONE_TO_MANY; | I6: New | J6: 08 CROSSWALK
A7: R1564-v1 | B7: Commercial Package Register / PKG-002 | C7: Package Code = PK-102; WBS Code = 1.1 | D7: Proposed by Source assignment; target 1.1 Guideway and Civil | E7: None recorded | F7: No individual professional decision recorded; Source assignment -- not individually reviewed | G7: Not individually decided | H7: APPROVED / ONE_TO_ONE; | I7: New | J7: 08 CROSSWALK
A8: R1565-v1 | B8: Commercial Package Register / PKG-003 | C8: Package Code = PK-103; WBS Code = 1.1 | D8: Proposed by Source assignment; target 1.1 Guideway and Civil | E8: None recorded | F8: No individual professional decision recorded; Source assignment -- not individually reviewed | G8: Not individually decided | H8: APPROVED / ONE_TO_ONE; | I8: New | J8: 08 CROSSWALK
A9: R1566-v1 | B9: Commercial Package Register / PKG-004 | C9: Package Code = PK-104; WBS Code = 1.1 | D9: Proposed by Source assignment; target 1.1 Guideway and Civil | E9: None recorded | F9: No individual professional decision recorded; Source assignment -- not individually reviewed | G9: Not individually decided | H9: APPROVED / ONE_TO_ONE; | I9: New | J9: 08 CROSSWALK
A10: R1567-v1 | B10: Commercial Package Register / PKG-005 | C10: Package Code = PK-105; WBS Code = 1.1 | D10: Proposed by Source assignment; target 1.1 Guideway and Civil | E10: None recorded | F10: No individual professional decision recorded; Source assignment -- not individually reviewed | G10: Not individually decided | H10: APPROVED / ONE_TO_ONE; | I10: New | J10: 08 CROSSWALK
A11: R1568-v1 | B11: Commercial Package Register / PKG-006 | C11: Package Code = PK-106; WBS Code = 1.1 | D11: Proposed by Source assignment; target 1.1 Guideway and Civil | E11: None recorded | F11: No individual professional decision recorded; Source assignment -- not individually reviewed | G11: Not individually decided | H11: APPROVED / ONE_TO_ONE; | I11: New | J11: 08 CROSSWALK
A12: R1569-v1 | B12: Commercial Package Register / PKG-007 | C12: Package Code = PK-107; WBS Code = 1.1 | D12: Proposed by Source assignment; target 1.1 Guideway and Civil | E12: None recorded | F12: No individual professional decision recorded; Source assignment -- not individually reviewed | G12: Not individually decided | H12: APPROVED / ONE_TO_ONE; | I12: New | J12: 08 CROSSWALK
A13: R1570-v1 | B13: Commercial Package Register / PKG-008 | C13: Package Code = PK-108; WBS Code = 1.1 | D13: Proposed by Source assignment; target 1.1 Guideway and Civil | E13: None recorded | F13: No individual professional decision recorded; Source assignment -- not individually reviewed | G13: Not individually decided | H13: APPROVED / ONE_TO_ONE; | I13: New | J13: 08 CROSSWALK
A14: R1571-v1 | B14: Commercial Package Register / PKG-009 | C14: Package Code = PK-109; WBS Code = 1.1 | D14: Proposed by Source assignment; target 1.1 Guideway and Civil | E14: None recorded | F14: No individual professional decision recorded; Source assignment -- not individually reviewed | G14: Not individually decided | H14: APPROVED / ONE_TO_ONE; | I14: New | J14: 08 CROSSWALK
A15: R1572-v1 | B15: Commercial Package Register / PKG-010 | C15: Package Code = PK-110; WBS Code = 1.1 | D15: Proposed by Source assignment; target 1.1 Guideway and Civil | E15: None recorded | F15: No individual professional decision recorded; Source assignment -- not individually reviewed | G15: Not individually decided | H15: APPROVED / ONE_TO_ONE; | I15: New | J15: 08 CROSSWALK
A16: R1-v1 | B16: Contractor Programme / SCH-01-001 | C16: WBS Code = 1.1.1 | D16: Proposed by Source assignment; target 1.1.1 Guideway and Civil - Guideway Structures | E16: None recorded | F16: No individual professional decision recorded; Source assignment -- not individually reviewed | G16: Not individually decided | H16: APPROVED / ONE_TO_ONE; | I16: New | J16: 08 CROSSWALK
... A1628: R1482-v2 | B1628: Cost & Forecast Control Accounts / CST-05-080 | C1628: Cost Account = CA-5080 | D1628: Proposed by Professional; target UNSURE | E1628: None recorded | F1628: Maya Chen, Owner Project Controls: Professional decision | G1628: Group decision (81 records sharing one decision state) | H1628: APPROVED / UNSURE; | I1628: New | J1628: 08 CROSSWALK

Sheet 11 SOURCES & PROVENANCE
A1: SOURCES & PROVENANCE
A2: The information boundary of this workbook. Supplied evidence is not the same as established interpretation.
A3: Executive | B3: Issues | C3: Integration | D3: Project | E3: Changes | F3: Crosswalk | G3: Evidence | H3: Sources
A5: Project source-representation integrity | B5: Established
A7: Source | B7: Governed role | C7: Revision | D7: Reporting period | E7: Rows | F7: Role basis | G7: Role validity | H7: Table boundary | I7: Interpretation | J7: Interpretation basis | K7: Format | L7: File integrity
A8: Commercial Package Register | B8: WORK_PACKAGE_LIST | C8: Rev 0 | D8: Initial | E8: 60 | F8: declared at upload | G8: AS_SUPPLIED | H8: ESTABLISHED | I8: TABLE | J8: SOURCE_NATIVE_SCHEMA | K8: xlsx | L8: SOURCE_REPRESENTATION_ESTABLISHED
A9: Contractor Programme | B9: SCHEDULE | C9: Rev 0 | D9: Initial | E9: 1082 | F9: declared at upload | G9: AS_SUPPLIED | H9: ESTABLISHED | I9: TABLE | J9: DETERMINISTIC_SEMANTIC_RELATION | K9: csv | L9: SOURCE_REPRESENTATION_ESTABLISHED
A10: Cost & Forecast Control Accounts | B10: COST_ESTIMATE | C10: Rev 0 | D10: Initial | E10: 480 | F10: declared at upload | G10: AS_SUPPLIED | H10: ESTABLISHED | I10: TABLE | J10: DETERMINISTIC_SEMANTIC_RELATION | K10: xlsx | L10: SOURCE_REPRESENTATION_ESTABLISHED
A11: Owner WBS | B11: WBS_DICTIONARY | C11: Rev 0 | D11: Initial | E11: 79 | F11: declared at upload | G11: AS_SUPPLIED | H11: ESTABLISHED | I11: TABLE | J11: DETERMINISTIC_SEMANTIC_RELATION | K11: xlsx | L11: SOURCE_REPRESENTATION_ESTABLISHED

Sheet 12 ASSURANCE
A1: ASSURANCE
A2: Exact governance detail and output boundaries. This sheet supports review; it does not create authority.
A3: Executive | B3: Issues | C3: Integration | D3: Project | E3: Changes | F3: Crosswalk | G3: Evidence | H3: Sources
A5: Assurance item | B5: Recorded value
A6: Output version | B6: Premium Workbook Rev 2
A7: Project | B7: HarbourLink Urban Transit Expansion
A8: Approved mapping version | B8: MV-1 (REPORTING)
A9: Approved by | B9: Maya Chen, Owner Project Controls
A10: Approved timestamp | B10: 2026-10-12 14:25 UTC
A11: WBS version | B11: 1
A12: Source-representation integrity | B12: SOURCE_REPRESENTATION_ESTABLISHED
A13: Source-integrity unresolved count | B13: 0
A14: Relationship rows | B14: 1623
A15: Generation timestamp | B15: 2026-10-13 13:45 UTC
A17: Interpretation boundary
A18: Workbook/App/JSON/PDF agreement can prove that outputs consume one governed state. It cannot prove that an upstream source interpretation is true. Source representation integrity is a separate prerequisite for substantive management claims.
A21: Known output limitations
A22: • Management amount/date/duration measures are withheld unless field semantics are explicitly governed for that use.
A23: • The workbook projects independent source structures through governed WBS relationships; it does not create direct source-to-source truth.
A24: • Sheet 04 (issues for review) is not a ranked list and does not claim objective materiality without a governed ranking basis.
A25: • Fictional evaluation case. No real-client provenance, privacy/security/compliance or hosting-residency claim is made by this workbook.
A27: Visual / metric ledger
A28: ID | B28: Title | C28: Management question | D28: Basis / population | E28: Unresolved treatment | F28: Transformation | G28: Drill path | H28: Records | I28: Status
A29: V1 | B29: WBS × control-view integration matrix | C29: Which supplied project-control views have governed relationships through each major Owner-WBS branch? | D29: Latest approved MappingVersion and its approved source-role basis. | Non-retired governed/open relationship population scoped through each displayed WBS branch. | E29: Unresolved is distinct from assessed zero coverage and source-not-supplied. | F29: Categorical state from supplied source role plus branch-scoped governed/open relationships; no health percentage. | G29: visual → WBS branch → integrated project → Crosswalk → evidence/professional decision | H29: 1357 | I29: AVAILABLE
A30: V2 | B30: Management-attention concentration by WBS branch | C30: Where are governed reopened, unresolved or contradictory relationship populations concentrated? | D30: Latest approved relationship state and retained relationship evidence. | Branch-scoped relationships with reopened/unresolved/contradictory evidence. | E30: Counts remain explicit; no record-count-to-materiality inference. | F30: Count qualifying relationship records by approved WBS branch; overlapping categories remain separately labelled. | G30: visual → WBS branch → Changes/What Matters Now → Crosswalk → evidence | H30: 2 | I30: AVAILABLE
A31: V3 | B31: Cycle governed-state composition | C31: How much relationship state carried forward versus required revalidation/redecision/new/retired treatment? | D31: Current approved MappingVersion change labels relative to prior approved state. | One current/historical change label per governed relationship version represented in output. | E31: Unresolved relationship outcome remains separate from change-state composition. | F31: Count governed relationships by the existing change labels; no speed/value claim inferred. | G31: visual → change class → Changes & Revalidation → relationship → evidence | H31: 1622 | I31: AVAILABLE
A32: V4 | B32: Governed cost / forecast view | C32: What governed cost/forecast amount can be shown by WBS scope? | D32: No sufficient quantitative contract supplied. | None admitted. | E32: All amount claims withheld. | F32: No aggregation performed. | G32: See Sources & Provenance / Assurance for withholding reason. | H32: 0 | I32: WITHHELD

Sheet 13 REVISIONS & PERIODS
A1: REVISIONS & PERIODS
A2: Which reporting revision this workbook is built on, what superseded what, and why only part of the governed relationship state reopened.
A3: Executive | B3: Issues | C3: Integration | D3: Project | E3: Changes | F3: Crosswalk | G3: Evidence | H3: Sources
A5: State of record | B5: MV-1 approved by Maya Chen, Owner Project Controls · 2026-10-12 14:25 UTC
A6: Built on these revisions | B6: Owner WBS (Initial Rev 0); Contractor Programme (Initial Rev 0); Cost & Forecast Control Accounts (Initial Rev 0); Commercial Package Register (Initial Rev 0)
A8: Selective revalidation in this version
A9: Relationships (unique) by change since the previous approved version -- the same composition as 07 CHANGES & REVALIDATION. Carried forward work was not rebuilt.
A10: Relationships in this version | B10: 1622
A11: Carried forward without rework | B11: 0
A12: Came back and were decided again (changed) | B12: 0
A13: New in this version | B13: 1622
A14: Retired (no longer reported) | B14: 0
A16: Source revision history
A17: Every revision supplied up to this approval, oldest first per source. CURRENT = the revision this version was approved against; SUPERSEDED = replaced within the same reporting period; HISTORICAL = the last revision of an earlier period. Added / Removed / Changed compare each revision's records with the previous revision of the same source (source content, not a relationship decision).
A18: Source | B18: Reporting period | C18: Revision | D18: Revision in period | E18: State | F18: Superseded by | G18: Effective from (UTC) | H18: Effective to (UTC) | I18: Data date | J18: Records | K18: Added | L18: Removed | M18: Changed | N18: Unchanged | O18: Approval basis | P18: File (SHA-256, first 12)
A19: Owner WBS | B19: Initial | C19: Rev 0 | D19: 0 | E19: CURRENT | G19: 2026-10-12 14:24:44 | I19: 2027-06-30 | J19: 79 | O19: Approved basis | P19: 37a40d25ac86
A20: Contractor Programme | B20: Initial | C20: Rev 0 | D20: 0 | E20: CURRENT | G20: 2026-10-12 14:24:45 | I20: 2027-06-30 | J20: 1082 | O20: Approved basis | P20: 3fd2ce3d07c0
A21: Cost & Forecast Control Accounts | B21: Initial | C21: Rev 0 | D21: 0 | E21: CURRENT | G21: 2026-10-12 14:24:46 | I21: 2027-06-30 | J21: 480 | O21: Approved basis | P21: f9ba38891271
A22: Commercial Package Register | B22: Initial | C22: Rev 0 | D22: 0 | E22: CURRENT | G22: 2026-10-12 14:24:47 | I22: 2027-06-30 | J22: 60 | O22: Approved basis | P22: 69e50b85c924
A24: Approval history
A25: Each approved mapping version, the source revisions it was approved against, and how much of its relationship state was carried forward versus decided again.
A26: Mapping version | B26: Status | C26: Approved by | D26: Approved at (UTC) | E26: Approved against | F26: Relationships | G26: Carried forward | H26: Changed, re-decided | I26: New | J26: Retired
A27: MV-1 | B27: State of record | C27: Maya Chen, Owner Project Controls | D27: 2026-10-12 14:25:37 | E27: Owner WBS (Initial Rev 0); Contractor Programme (Initial Rev 0); Cost & Forecast Control Accounts (Initial Rev 0); Commercial Package Register (Initial Rev 0) | F27: 1622 | G27: 0 | H27: 0 | I27: 1622 | J27: 0
A29: Came back for a decision in this version
A30: Only these relationships were reopened, new or retired; every other relationship was carried forward with its original basis and approver.
A31: Relationship | B31: Record | C31: Change | D31: Reason | E31: Decided by | F31: Evidence
A32: R1083-v1 | B32: CST-01-001 | C32: New | D32: Record first supplied in this revision | F32: 10 EVIDENCE & DECISIONS
A33: R1084-v1 | B33: CST-01-002 | C33: New | D33: Record first supplied in this revision | F33: 10 EVIDENCE & DECISIONS
A34: R1085-v1 | B34: CST-01-003 | C34: New | D34: Record first supplied in this revision | F34: 10 EVIDENCE & DECISIONS
A35: R1086-v1 | B35: CST-01-004 | C35: New | D35: Record first supplied in this revision | F35: 10 EVIDENCE & DECISIONS
A36: R1087-v1 | B36: CST-01-005 | C36: New | D36: Record first supplied in this revision | F36: 10 EVIDENCE & DECISIONS
A37: R1088-v1 | B37: CST-01-006 | C37: New | D37: Record first supplied in this revision | F37: 10 EVIDENCE & DECISIONS
A38: R1089-v1 | B38: CST-01-007 | C38: New | D38: Record first supplied in this revision | F38: 10 EVIDENCE & DECISIONS
A39: R1090-v1 | B39: CST-01-008 | C39: New | D39: Record first supplied in this revision | F39: 10 EVIDENCE & DECISIONS
A40: R1091-v1 | B40: CST-01-009 | C40: New | D40: Record first supplied in this revision | F40: 10 EVIDENCE & DECISIONS
A41: R1092-v1 | B41: CST-01-010 | C41: New | D41: Record first supplied in this revision | F41: 10 EVIDENCE & DECISIONS
A42: R1093-v1 | B42: CST-01-011 | C42: New | D42: Record first supplied in this revision | F42: 10 EVIDENCE & DECISIONS
A43: R1094-v1 | B43: CST-01-012 | C43: New | D43: Record first supplied in this revision | F43: 10 EVIDENCE & DECISIONS
... A194: R1245-v1 | B194: CST-03-003 | C194: New | D194: Record first supplied in this revision | F194: 10 EVIDENCE & DECISIONS
A195: R1246-v2 | B195: CST-03-004 | C195: New | D195: Record first supplied in this revision | E195: Maya Chen, Owner Project Controls | F195: 10 EVIDENCE & DECISIONS
...

Sheet 14 WBS HIERARCHY
A1: WBS HIERARCHY
A2: The approved WBS as a scope hierarchy. Use the outline buttons (1, 2, 3 ...) at the left to collapse or expand levels; counts recalculate from MASTER DATA.
A3: Executive | B3: Issues | C3: Integration | D3: Project | E3: Changes | F3: Crosswalk | G3: Evidence | H3: Sources
