Workbook
Name WBSLINK_GOVERNED_RECORDS: 'MASTER DATA'!$A$1:$W$1627

Sheet 01 PROJECT
A2: ZP SYNERGY GROUP INC.
A4: WBS↔LINK™
A5: Premium Integrated Project Controls Workbook
A7: HarbourLink Urban Transit Expansion
A10: Workbook state | B10: Approved project-controls relationship state
A11: Reporting / data date | B11: 2026-07-31 (Contractor Programme Rev 1); 2026-07-31 (Cost & Forecast Control Accounts Rev 1); 2026-07-31 (Commercial Package Register Rev 1)
A12: Approved by | B12: Maya Chen, Owner Project Controls
A13: Approved (UTC) | B13: 2026-10-16 14:14
A14: WBS version | B14: 1
A15: Source set | B15: Commercial Package Register (WORK_PACKAGE_LIST, Rev 1); Contractor Programme (SCHEDULE, Rev 1); Cost & Forecast Control Accounts (COST_ESTIMATE, Rev 1); Owner WBS (WBS_DICTIONARY, Rev 0)
A18: HarbourLink is a fictional infrastructure example. Owner WBS is the owner’s common list of project work. Begin with one approved finding, then follow its original source and professional authority. Use the Management Report PDF for the executive print route; this workbook is the deeper working evidence tool.
A22: Begin with 02 START HERE →

Sheet 02 START HERE
A1: HOW TO USE THIS WORKBOOK
A2: Owner WBS is the owner’s common list of project work. Compare schedule, cost and work packages; follow one finding to original evidence.
A3: Executive | B3: Issues | C3: Integration | D3: Project | E3: Changes | F3: Crosswalk | G3: Evidence | H3: Sources
A5: Start with your task | B5: Purpose and next step | D5: ONE FINDING → ITS AUTHORITY
A6: Executive | Position | B6: Read the approved position; four governed charts and their source tables. | D6: 1 Read the approved position
A7: Controls | Issues | B7: Choose one issue and its exact professional Action. Issues are not ranked.
A8: Controls | WBS scope | B8: Primary WBS view: governed relationship coverage/status. Then open Crosswalk. | D8: 2 Choose the exact professional Action
A9: Analyst | Crosswalk | B9: Filter WBS code / Source Record ID; follow the stable Relationship ID.
A10: Analyst | Evidence | B10: Match Relationship ID: source assertion, interpretation, contrary evidence, human decision. | D10: 3 Match the original source record
A11: Controls | Cycle change | B11: Inspect the approved-cycle movement and what returned for review.
A12: Assurance | Sources | B12: Identify source, approved revision and original representation. | D12: 4 Inspect evidence and separate approval
A13: Assurance | Withholding | B13: Check withholding, approved basis and definitions.
D15: Coverage is not project health. Cost / forecast totals remain withheld.
A17: One evidence path
A18: Approved position → named finding → Owner WBS → Crosswalk → original source / interpretation → professional decision → separate approval. Compare the next cycle only after reading the approved baseline.
A22: Supporting diagnostics and scope detail
A23: 13 REVISIONS & PERIODS | B23: See which reporting revision each source is on, what superseded what, and why only part of the relationship state reopened.
A24: 14 WBS HIERARCHY | B24: Approved scope tree and direct/branch relationship ROW counts. Split targets may create multiple rows; retired rows are included unless filtered. Not interchangeable with 09 WBS EXPLORER.
A25: 15 ANALYSIS | B25: Cross-tabulate governed dimensions from MASTER DATA (formulas, self-checking).
A28: EXECUTIVE | B28: Start at 03 EXECUTIVE VIEW. Read the position, exact Actions and withholding; inspect the four figures when a question needs diagnosis.
A29: PROJECT CONTROLS | B29: Start at 04 ISSUES FOR REVIEW. Choose a finding, open its WBS scope in 09, then follow the actual source record and stable Relationship ID.
A30: EVIDENCE | B30: Start at 10 EVIDENCE & DECISIONS. Match the stable Relationship ID to source assertion, interpretation, contrary evidence and the recorded professional decision. Check approval-time sources in 11.
A31: ASSURANCE / SOURCES | B31: Use 12 ASSURANCE for withholding and counting definitions; 13 REVISIONS & PERIODS records lineage. Approval is separate from a record-level decision.
A32: STUDENT · HARBOURLINK | B32: Start at WBS 1.5 Testing and Commissioning. Compare schedule and cost coverage; follow the issue to Crosswalk and Evidence. Inspect the recorded decision, then Cycle 2 Changes. This is a synthetic example, not an answer key.
A34: Tab groups | B34: Cognac: orientation. Navy: executive decisions. Navy veil: diagnostics. Grey: source and assurance evidence. Steel: advanced and compatibility views. Colours support the sheet names; they do not indicate risk or project health.
A35: Why the counts differ | B35: 09 WBS EXPLORER counts distinct relationship coverage/status. 14 WBS HIERARCHY counts relationship ROWS per target, including split targets and retired rows unless filtered. Current movement, issue groups and unplaced outcomes have different populations.
A37: Advanced evidence and supporting views
A38: 05 INTEGRATION HEALTH | B38: Cross-view relationship availability and gated analytical populations.
A39: 06 INTEGRATED PROJECT | B39: Supporting cross-view projections by WBS; use 09 for first scope navigation.
A40: MASTER DATA | B40: Compatibility/formula source table; one row per relationship target.
A41: OWNER WBS | B41: Approved source scope tree; original names, ancestry and evidence retained.
A42: RELATIONSHIP EXPLORER | B42: Advanced formula-based target-row explorer; 09 is the primary scope view.
A43: UNRESOLVED | B43: Supporting outcome records; uncertainty is not assessed outside scope.
A44: HISTORY | B44: Compatibility approved-version history; 13 provides revision lineage.
A45: SUMMARY | B45: Compatibility calculations; 03 is the canonical executive decision surface.
A50: All-sheet purpose index | B50: Role and counting population
A51: 01 PROJECT | B51: Publication identity, approved version and source-set orientation; then open the index.
A52: 02 START HERE | B52: Primary task index and discoverable supporting/advanced destinations.
A53: 03 EXECUTIVE VIEW | B53: Canonical executive decision surface and four retained native charts.
... A71: SUMMARY | B71: Compatibility calculations; 03 is the canonical executive decision surface.

Sheet 03 EXECUTIVE VIEW
A1: EXECUTIVE VIEW
A2: HarbourLink Urban Transit Expansion · approved integrated project view | G2: Owner WBS: the owner’s common list of project work. Gaps need checking; coverage does not prove performance.
A3: Executive | C3: Issues | E3: Integration | G3: Project
A4: Changes | C4: Crosswalk | E4: Evidence | G4: Sources
A5: WHERE THE PROJECT STANDS | E5: ISSUES AND WITHHOLDING
A6: 4 / 6 Owner-WBS branches schedule AND cost present | E6: 1. 1.5 Testing and Commissioning: Schedule without cost coverage. 2. 1.6 Program Management: Cost without schedule coverage. 3. 264 items still need more information before they can be placed in the Owner WBS
A8: 1.1 Guideway and Civil Schedule: Present · Cost: Present 1.2 Stations Schedule: Present · Cost: Present 1.3 Systems Schedule: Present · Cost: Present 1.4 Vehicles and Depot Schedule: Present · Cost: Present 1.5 Testing and Commissioning Schedule: Present · Cost: ABSENT 1.6 Program Management Schedule: ABSENT · Cost: Present
E9: Cost / forecast total: Withheld. Aggregation eligibility is not established. See 12 ASSURANCE.
A10: Next step: Confirm whether the missing governed relationship is expected or requires project-controls attention. (3 issues on sheet 04.)
A11: Issues for review | C11: Current relationships not carried forward | E11: Reopened this cycle | G11: Source integrity
A12: 3 | C12: 9 | E12: 5 | G12: Established
A13: Listed on sheet 04 | C13: Includes re-keyed/revalidated; excludes retired | E13: Event count; issues needing attention now are on sheet 04 | G13: Upstream truth gate
A15: Review the issues → | C15: Open Integration Health → | E15: Open Changes → | G15: Prove it in Crosswalk →
A18: What this workbook cannot establish
A19: • Amount/date/duration management measures are withheld unless their field semantics are explicitly governed for that use.
A21: 1 · Schedule and cost relationships by WBS branch | E21: 2 · Relationship outcomes by source
A23: 4 of 6 WBS branches carry both schedule and cost relationships; 2 branches are covered by only one of them. | E23: 1,357 of 1,622 current relationships relate a source record to a WBS element, across 3 source documents. 265 are recorded outside the WBS or left unresolved.
A26: Out of 6 reported WBS branches. Coverage is observed through the WBS; it is not a direct schedule-to-cost link. Detail: 05 INTEGRATION HEALTH. | E26: Out of 1,622 current relationships (retired relationships excluded); one relationship counted once even when split across several WBS elements. Detail: 08 CROSSWALK.
A51: 3 · Changes since the previous approved version | E51: 4 · Outcomes left unresolved or outside the WBS
A53: 1,613 of 1,625 relationships carried forward unchanged; 12 were re-keyed, changed, new or retired. | E53: 265 of 1,622 current relationships are left unresolved or recorded outside the approved WBS. Rely only on conclusions that do not depend on them; sheet 04 groups them into the issues for review.
A56: Out of 1,625 relationships, including retired ones, by change label. Detail: 07 CHANGES & REVALIDATION. | E56: Out of 1,622 current relationships (retired excluded). These are recorded, governed outcomes, not errors. Detail: sheet 04 (issues for review) and 08 CROSSWALK.
A83: FOUR VIEWS OF THE APPROVED PROJECT
A84: Each chart draws on the approved relationship records. It states what it counts, the population covered and the source table beneath it.
A86: 1 · Schedule and cost relationships by WBS branch
A87: 4 of 6 WBS branches carry both schedule and cost relationships; 2 branches are covered by only one of them.
A88: Out of 6 reported WBS branches. Coverage is observed through the WBS; it is not a direct schedule-to-cost link. Detail: 05 INTEGRATION HEALTH.
A104: WBS branches | C104: Count
A105: Schedule and cost | C105: 4
A106: Schedule only | C106: 1
A107: Cost only | C107: 1
A108: Neither schedule nor cost | C108: 0
A109: Total WBS branches | C109: 6
A111: 2 · Relationship outcomes by source
A112: 1,357 of 1,622 current relationships relate a source record to a WBS element, across 3 source documents. 265 are recorded outside the WBS or left unresolved.
A113: Out of 1,622 current relationships (retired relationships excluded); one relationship counted once even when split across several WBS elements. Detail: 08 CROSSWALK.
A129: Source document | C129: Related to a WBS element | E129: Recorded outside the WBS | G129: Left unresolved | I129: Total
A130: Commercial Package Register | C130: 59 | E130: 0 | G130: 1 | I130: 60
A131: Contractor Programme | C131: 899 | E131: 1 | G131: 182 | I131: 1082
A132: Cost & Forecast Control Accounts | C132: 399 | E132: 0 | G132: 81 | I132: 480
A133: All sources | C133: 1357 | E133: 1 | G133: 264 | I133: 1622
...

Sheet 04 ISSUES FOR REVIEW
A1: ISSUES FOR REVIEW
A2: The issues the governed evidence supports raising with the project team now. Grouped by type and WBS code; not ranked by importance.
A3: Executive | B3: Issues | C3: Integration | D3: Project | E3: Changes | F3: Crosswalk | G3: Evidence | H3: Sources
A5: Matter | B5: Why it matters | C5: Affected WBS scope | D5: Affected source view(s) | E5: State | F5: Recommended professional action | G5: Evidence path | H5: Authority
A6: Schedule scope has no governed cost relationships | B6: The supplied schedule and cost views do not both project through this approved WBS branch. | C6: 1.5 Testing and Commissioning | D6: Schedule + Cost | E6: Derived observation from governed relationships | F6: Confirm whether the missing governed relationship is expected or requires project-controls attention. | G6: 05 INTEGRATION HEALTH / 08 CROSSWALK: WBS 1.5 | H6: Derived observation; no direct schedule↔cost relationship asserted
A7: Cost scope has no governed schedule relationships | B7: The supplied schedule and cost views do not both project through this approved WBS branch. | C7: 1.6 Program Management | D7: Schedule + Cost | E7: Derived observation from governed relationships | F7: Confirm whether the missing governed relationship is expected or requires project-controls attention. | G7: 05 INTEGRATION HEALTH / 08 CROSSWALK: WBS 1.6 | H7: Derived observation; no direct schedule↔cost relationship asserted
A8: 264 relationship outcome(s) remain deliberately unresolved | B8: The approved state preserves uncertainty rather than forcing a WBS relationship. | C8: See Crosswalk | D8: See Crosswalk | E8: Professionally/governed unresolved outcome | F8: Use only conclusions that do not depend on these unresolved relationships. | G8: 08 CROSSWALK / 10 EVIDENCE & DECISIONS | H8: Governed uncertainty
A10: Ordering note: matters are grouped deterministically by governed matter class and WBS code. No claim of objective project materiality or #1 priority is made.

Sheet 05 INTEGRATION HEALTH
A1: INTEGRATION HEALTH
A2: WBS branch view of governed project-control relationships. No single aggregate health percentage is asserted.
A3: Executive | B3: Issues | C3: Integration | D3: Project | E3: Changes | F3: Crosswalk | G3: Evidence | H3: Sources | K3: V2 · WHERE PROFESSIONAL ATTENTION IS CONCENTRATED
K4: Where are governed reopened, unresolved or contradictory relationship populations concentrated?
A5: WBS | B5: Scope | C5: Schedule | D5: Cost / forecast | E5: Package / contract | F5: Integration condition | G5: Attention / unresolved | H5: Changed | I5: Evidence path | K5: WBS | L5: Reopened | M5: Unresolved | N5: Contradictory | O5: Attention records
A6: 1.1 | B6: Guideway and Civil | C6: 181 governed relationships | D6: 81 governed relationships | E6: 9 governed relationships | F6: Aligned: Schedule and cost both relate through this WBS branch. 9 package/contract relationships also project through this branch. | G6: 0 | H6: 5 | I6: 06 INTEGRATED PROJECT / 08 CROSSWALK: WBS 1.1 | K6: 1.2 | L6: 2 | M6: 0 | N6: 1 | O6: 3
A7: 1.2 | B7: Stations | C7: 180 governed relationships | D7: 80 governed relationships | E7: 12 governed relationships | F7: Aligned: Schedule and cost both relate through this WBS branch. 12 package/contract relationships also project through this branch. | G7: 0 | H7: 2 | I7: 06 INTEGRATED PROJECT / 08 CROSSWALK: WBS 1.2 | K7: 1.1 | L7: 2 | M7: 0 | N7: 1 | O7: 3
A8: 1.3 | B8: Systems | C8: 179 governed relationships | D8: 79 governed relationships | E8: 10 governed relationships | F8: Aligned: Schedule and cost both relate through this WBS branch. 10 package/contract relationships also project through this branch. | G8: 0 | H8: 0 | I8: 06 INTEGRATED PROJECT / 08 CROSSWALK: WBS 1.3 | K8: 1.4 | L8: 0 | M8: 0 | N8: 0 | O8: 0
A9: 1.4 | B9: Vehicles and Depot | C9: 179 governed relationships | D9: 80 governed relationships | E9: 10 governed relationships | F9: Aligned: Schedule and cost both relate through this WBS branch. 10 package/contract relationships also project through this branch. | G9: 0 | H9: 0 | I9: 06 INTEGRATED PROJECT / 08 CROSSWALK: WBS 1.4 | K9: 1.3 | L9: 0 | M9: 0 | N9: 0 | O9: 0
A10: 1.5 | B10: Testing and Commissioning | C10: 180 governed relationships | D10: 0 governed relationships | E10: 10 governed relationships | F10: Attention: Schedule scope has no governed cost relationships in this WBS branch. 10 package/contract relationships also project through this branch. | G10: 0 | H10: 0 | I10: 06 INTEGRATED PROJECT / 08 CROSSWALK: WBS 1.5 | K10: 1.5 | L10: 0 | M10: 0 | N10: 0 | O10: 0
A11: 1.6 | B11: Program Management | C11: 0 governed relationships | D11: 79 governed relationships | E11: 9 governed relationships | F11: Attention: Cost scope has no governed schedule relationships in this WBS branch. 9 package/contract relationships also project through this branch. | G11: 0 | H11: 0 | I11: 06 INTEGRATED PROJECT / 08 CROSSWALK: WBS 1.6 | K11: 1.6 | L11: 0 | M11: 0 | N11: 0 | O11: 0
K12: Counts locate governed professional-attention populations only; they are not financial or schedule materiality rankings.
B13: V1 · WBS × CONTROL-VIEW INTEGRATION MATRIX
B14: Which supplied project-control views have governed relationships through each major Owner-WBS branch?
B16: WBS | C16: Scope | D16: Schedule | E16: Cost / forecast | F16: Package / contract | G16: Responsibility | H16: Proof path
B17: 1.2 | C17: Stations | D17: 180 governed relationships | E17: 80 governed relationships | F17: 12 governed relationships | G17: Not supplied | H17: 06 INTEGRATED PROJECT / 08 CROSSWALK: WBS 1.2
B18: 1.1 | C18: Guideway and Civil | D18: 181 governed relationships | E18: 81 governed relationships | F18: 9 governed relationships | G18: Not supplied | H18: 06 INTEGRATED PROJECT / 08 CROSSWALK: WBS 1.1
B19: 1.4 | C19: Vehicles and Depot | D19: 179 governed relationships | E19: 80 governed relationships | F19: 10 governed relationships | G19: Not supplied | H19: 06 INTEGRATED PROJECT / 08 CROSSWALK: WBS 1.4
B20: 1.3 | C20: Systems | D20: 179 governed relationships | E20: 79 governed relationships | F20: 10 governed relationships | G20: Not supplied | H20: 06 INTEGRATED PROJECT / 08 CROSSWALK: WBS 1.3
B21: 1.5 | C21: Testing and Commissioning | D21: 180 governed relationships | E21: Assessed · no governed coverage | F21: 10 governed relationships | G21: Not supplied | H21: 06 INTEGRATED PROJECT / 08 CROSSWALK: WBS 1.5
B22: 1.6 | C22: Program Management | D22: Assessed · no governed coverage | E22: 79 governed relationships | F22: 9 governed relationships | G22: Not supplied | H22: 06 INTEGRATED PROJECT / 08 CROSSWALK: WBS 1.6
B23: Unresolved is distinct from assessed zero coverage and source-not-supplied.
A25: V4 · COST / FORECAST VISUAL WITHHELD
A26: Withheld: current generic field-name recognition is not a governed quantitative contract. Measure meaning, currency/unit, period, grain, WBS basis, allocation and unresolved treatment must all be established.

Sheet 06 INTEGRATED PROJECT
A1: INTEGRATED PROJECT
A2: Working projection of independently authored project views through the approved WBS integration spine.
A3: Executive | B3: Issues | C3: Integration | D3: Project | E3: Changes | F3: Crosswalk | G3: Evidence | H3: Sources
A5: WBS | B5: Scope | C5: Schedule relationships | D5: Cost relationships | E5: Package / contract relationships | F5: Other relationships | G5: Open / unresolved | H5: Changed | I5: Current integration observation | J5: Drill to proof
B6: HarbourLink Urban Transit Expansion | C6: 899 governed relationships | D6: 399 governed relationships | E6: 59 governed relationships | F6: 0 governed relationships | G6: 0 | H6: 7 | I6: Schedule and cost both relate through this WBS branch. 59 package/contract relationships also project through this branch. | J6: 08 CROSSWALK: WBS
A7: 1 | B7: HarbourLink Urban Transit Expansion | C7: 899 governed relationships | D7: 399 governed relationships | E7: 59 governed relationships | F7: 0 governed relationships | G7: 0 | H7: 7 | I7: Schedule and cost both relate through this WBS branch. 59 package/contract relationships also project through this branch. | J7: 08 CROSSWALK: WBS 1
A8: 1.1 | B8: Guideway and Civil | C8: 181 governed relationships | D8: 81 governed relationships | E8: 9 governed relationships | F8: 0 governed relationships | G8: 0 | H8: 5 | I8: Schedule and cost both relate through this WBS branch. 9 package/contract relationships also project through this branch. | J8: 08 CROSSWALK: WBS 1.1
A9: 1.1.1 | B9: Guideway and Civil - Guideway Structures | C9: 120 governed relationships | D9: 40 governed relationships | E9: 0 governed relationships | F9: 0 governed relationships | G9: 0 | H9: 3 | I9: Schedule and cost both relate through this WBS branch. | J9: 08 CROSSWALK: WBS 1.1.1
A10: 1.1.1.1 | B10: Guideway Structures - East Segment | C10: 0 governed relationships | D10: 0 governed relationships | E10: 0 governed relationships | F10: 0 governed relationships | G10: 0 | H10: 0 | I10: No governed schedule or cost relationships in this WBS branch. | J10: 08 CROSSWALK: WBS 1.1.1.1
A11: 1.1.1.2 | B11: Guideway Structures - West Segment | C11: 0 governed relationships | D11: 0 governed relationships | E11: 0 governed relationships | F11: 0 governed relationships | G11: 0 | H11: 0 | I11: No governed schedule or cost relationships in this WBS branch. | J11: 08 CROSSWALK: WBS 1.1.1.2
A12: 1.1.2 | B12: Guideway and Civil - Utility & Roadworks | C12: 61 governed relationships | D12: 41 governed relationships | E12: 0 governed relationships | F12: 0 governed relationships | G12: 0 | H12: 2 | I12: Schedule and cost both relate through this WBS branch. | J12: 08 CROSSWALK: WBS 1.1.2
A13: 1.1.2.1 | B13: Utility & Roadworks - East Segment | C13: 0 governed relationships | D13: 0 governed relationships | E13: 0 governed relationships | F13: 0 governed relationships | G13: 0 | H13: 0 | I13: No governed schedule or cost relationships in this WBS branch. | J13: 08 CROSSWALK: WBS 1.1.2.1
A14: 1.1.2.2 | B14: Utility & Roadworks - West Segment | C14: 0 governed relationships | D14: 0 governed relationships | E14: 0 governed relationships | F14: 0 governed relationships | G14: 0 | H14: 0 | I14: No governed schedule or cost relationships in this WBS branch. | J14: 08 CROSSWALK: WBS 1.1.2.2
A15: 1.1.3 | B15: Guideway and Civil - Track Support Works | C15: 0 governed relationships | D15: 0 governed relationships | E15: 0 governed relationships | F15: 0 governed relationships | G15: 0 | H15: 0 | I15: No governed schedule or cost relationships in this WBS branch. | J15: 08 CROSSWALK: WBS 1.1.3
A16: 1.1.3.1 | B16: Track Support Works - East Segment | C16: 0 governed relationships | D16: 0 governed relationships | E16: 0 governed relationships | F16: 0 governed relationships | G16: 0 | H16: 0 | I16: No governed schedule or cost relationships in this WBS branch. | J16: 08 CROSSWALK: WBS 1.1.3.1
A17: 1.1.3.2 | B17: Track Support Works - West Segment | C17: 0 governed relationships | D17: 0 governed relationships | E17: 0 governed relationships | F17: 0 governed relationships | G17: 0 | H17: 0 | I17: No governed schedule or cost relationships in this WBS branch. | J17: 08 CROSSWALK: WBS 1.1.3.2
A18: 1.1.4 | B18: Guideway and Civil - Civil Interfaces | C18: 0 governed relationships | D18: 0 governed relationships | E18: 0 governed relationships | F18: 0 governed relationships | G18: 0 | H18: 0 | I18: No governed schedule or cost relationships in this WBS branch. | J18: 08 CROSSWALK: WBS 1.1.4
... A85: 1.6.4.2 | B85: Delivery Integration - Delivery Partners | C85: 0 governed relationships | D85: 0 governed relationships | E85: 0 governed relationships | F85: 0 governed relationships | G85: 0 | H85: 0 | I85: No governed schedule or cost relationships in this WBS branch. | J85: 08 CROSSWALK: WBS 1.6.4.2

Sheet 07 CHANGES & REVALIDATION
A1: CHANGES & REVALIDATION
A2: What changed that matters, what remained valid, and where revalidation occurred.
A3: Executive | B3: Issues | C3: Integration | D3: Project | E3: Changes | F3: Crosswalk | G3: Evidence | H3: Sources
A5: Current approved state versus prior approved state | D5: V3 · CYCLE CONTINUITY
A6: Carried forward | B6: 1613 | D6: How much relationship state carried forward versus required revalidation/redecision/new/retired treatment?
A7: Re-keyed, revalidated | B7: 1
A8: Changed, re-decided | B8: 4
A9: New | B9: 4 | D9: Read the counts at left as governed relationship-state composition. Carried forward / revalidated means prior work did not need to be rebuilt; reopened/new/retired remain inspectable below.
A10: Retired | B10: 3
A12: Relationship | B12: Source | C12: Record | D12: WBS | E12: Change state | F12: Reopen / revalidation reason | G12: Decision provenance | H12: Evidence path
A13: R1085-v2 | B13: Cost & Forecast Control Accounts | C13: CST-01-003R | D13: 1.1.1 Guideway and Civil - Guideway Structures | E13: Re-keyed, revalidated | G13: Source assignment -- not individually reviewed | H13: 10 EVIDENCE & DECISIONS
A14: R1623-v1 | B14: Contractor Programme | C14: SCH-90-903 | D14: 1.1.1 Guideway and Civil - Guideway Structures | E14: New | G14: Source assignment -- not individually reviewed | H14: 10 EVIDENCE & DECISIONS
A15: R1624-v1 | B15: Cost & Forecast Control Accounts | C15: CST-90-903 | D15: 1.1.1 Guideway and Civil - Guideway Structures | E15: New | G15: Source assignment -- not individually reviewed | H15: 10 EVIDENCE & DECISIONS
A16: R1087-v3 | B16: Cost & Forecast Control Accounts | C16: CST-01-005 | D16: 1.1.2 Guideway and Civil - Utility & Roadworks | E16: Changed, re-decided | F16: 'WBS Code' changed from 1.1.1 to 1.1.2; 'WBS Code' changed from 1.1.1 to 1.1.2; 'WBS Code' changed from 1.1.1 to 1.1.2 | G16: Maya Chen, Owner Project Controls | H16: 10 EVIDENCE & DECISIONS
A17: R5-v3 | B17: Contractor Programme | C17: SCH-01-005 | D17: 1.1.2 Guideway and Civil - Utility & Roadworks | E17: Changed, re-decided | F17: 'WBS Code' changed from 1.1.1 to 1.1.2; 'WBS Code' changed from 1.1.1 to 1.1.2; 'WBS Code' changed from 1.1.1 to 1.1.2 | G17: Maya Chen, Owner Project Controls | H17: 10 EVIDENCE & DECISIONS
A18: R1567-v3 | B18: Commercial Package Register | C18: PKG-005 | D18: 1.2 Stations | E18: Changed, re-decided | F18: 'WBS Code' changed from 1.1 to 1.2; 'WBS Code' changed from 1.1 to 1.2; 'WBS Code' changed from 1.1 to 1.2 | G18: Maya Chen, Owner Project Controls | H18: 10 EVIDENCE & DECISIONS
A19: R183-v4 | B19: Contractor Programme | C19: SCH-02-003 | D19: 1.2.2 Stations - Architectural Fit-Out | E19: New | F19: 'WBS Code' changed from (blank) to 1.2.2; 'WBS Code' changed from (blank) to 1.2.2; 'WBS Code' changed from (blank) to 1.2.2 | G19: Maya Chen, Owner Project Controls | H19: 10 EVIDENCE & DECISIONS
A20: R1621-v2 | B20: Commercial Package Register | C20: PKG-059 | D20: 1.6 Program Management | E20: Retired | G20: Retired -- no longer reported | H20: 10 EVIDENCE & DECISIONS
A21: R1561-v2 | B21: Cost & Forecast Control Accounts | C21: CST-06-079 | D21: 1.6.1 Program Management - Program Controls | E21: Retired | G21: Retired -- no longer reported | H21: 10 EVIDENCE & DECISIONS
A22: R1081-v3 | B22: Contractor Programme | C22: SCH-90-901 | D22: NEW_SCOPE | E22: Retired | G22: Retired -- no longer reported | H22: 10 EVIDENCE & DECISIONS
A23: R1625-v2 | B23: Commercial Package Register | C23: PKG-903 | D23: UNSURE | E23: New | G23: Maya Chen, Owner Project Controls | H23: 10 EVIDENCE & DECISIONS
A24: R367-v3 | B24: Contractor Programme | C24: SCH-03-007 | D24: UNSURE | E24: Changed, re-decided | F24: 'WBS Code' changed from 1.3.1 to (blank); 'WBS Code' changed from 1.3.1 to (blank); 'WBS Code' changed from 1.3.1 to (blank) | G24: Maya Chen, Owner Project Controls | H24: 10 EVIDENCE & DECISIONS
A25: R1563-v3 | B25: Commercial Package Register | C25: PKG-001 | D25: 1.1 Guideway and Civil | E25: Carried forward | G25: Maya Chen, Owner Project Controls | H25: 10 EVIDENCE & DECISIONS
A26: R1564-v2 | B26: Commercial Package Register | C26: PKG-002 | D26: 1.1 Guideway and Civil | E26: Carried forward | G26: Source assignment -- not individually reviewed | H26: 10 EVIDENCE & DECISIONS
A27: R1565-v2 | B27: Commercial Package Register | C27: PKG-003 | D27: 1.1 Guideway and Civil | E27: Carried forward | G27: Source assignment -- not individually reviewed | H27: 10 EVIDENCE & DECISIONS
A28: R1566-v2 | B28: Commercial Package Register | C28: PKG-004 | D28: 1.1 Guideway and Civil | E28: Carried forward | G28: Source assignment -- not individually reviewed | H28: 10 EVIDENCE & DECISIONS
A29: R1568-v2 | B29: Commercial Package Register | C29: PKG-006 | D29: 1.1 Guideway and Civil | E29: Carried forward | G29: Source assignment -- not individually reviewed | H29: 10 EVIDENCE & DECISIONS
A30: R1569-v2 | B30: Commercial Package Register | C30: PKG-007 | D30: 1.1 Guideway and Civil | E30: Carried forward | G30: Source assignment -- not individually reviewed | H30: 10 EVIDENCE & DECISIONS
A31: R1570-v2 | B31: Commercial Package Register | C31: PKG-008 | D31: 1.1 Guideway and Civil | E31: Carried forward | G31: Source assignment -- not individually reviewed | H31: 10 EVIDENCE & DECISIONS
A32: R1571-v2 | B32: Commercial Package Register | C32: PKG-009 | D32: 1.1 Guideway and Civil | E32: Carried forward | G32: Source assignment -- not individually reviewed | H32: 10 EVIDENCE & DECISIONS
A33: R1572-v2 | B33: Commercial Package Register | C33: PKG-010 | D33: 1.1 Guideway and Civil | E33: Carried forward | G33: Source assignment -- not individually reviewed | H33: 10 EVIDENCE & DECISIONS
A34: R1-v2 | B34: Contractor Programme | C34: SCH-01-001 | D34: 1.1.1 Guideway and Civil - Guideway Structures | E34: Carried forward | G34: Source assignment -- not individually reviewed | H34: 10 EVIDENCE & DECISIONS
A35: R10-v2 | B35: Contractor Programme | C35: SCH-01-010 | D35: 1.1.1 Guideway and Civil - Guideway Structures | E35: Carried forward | G35: Source assignment -- not individually reviewed | H35: 10 EVIDENCE & DECISIONS
A36: R100-v2 | B36: Contractor Programme | C36: SCH-01-100 | D36: 1.1.1 Guideway and Civil - Guideway Structures | E36: Carried forward | G36: Source assignment -- not individually reviewed | H36: 10 EVIDENCE & DECISIONS
... A1637: R999-v3 | B1637: Contractor Programme | C1637: SCH-06-099 | D1637: UNSURE | E1637: Carried forward | G1637: Maya Chen, Owner Project Controls | H1637: 10 EVIDENCE & DECISIONS

Sheet 08 CROSSWALK
A1: CROSSWALK
A2: Inspectable relationship truth: source record → governed relationship → WBS target.
A3: Executive | B3: Issues | C3: Integration | D3: Project | E3: Changes | F3: Crosswalk | G3: Evidence | H3: Sources
A5: Source | B5: Record | C5: Description | D5: Source assertion | E5: Relationship | F5: Target WBS | G5: Relationship type | H5: Lifecycle state | I5: Change | J5: Basis / origin | K5: Decided by | L5: Target status | M5: Contrary evidence | N5: Evidence & decisions
A6: Commercial Package Register | B6: PKG-001 | C6: Guideway Civil Works | D6: Package Code = PK-101; WBS Code = 1.1;1.2 | E6: R1563-v3 | F6: 1.1 Guideway and Civil | G6: ONE_TO_MANY | H6: RETAINED | I6: Carried forward | J6: Earlier professional decision, carried forward | K6: Maya Chen, Owner Project Controls | M6: Source states 'WBS Code' = '1.1;1.2' -- names no element of this WBS -- professional reason (Maya Chen, Owner Project Controls): Source package register explicitly states both Owner-WBS branches. | N6: 10 EVIDENCE & DECISIONS
A7: Commercial Package Register | B7: PKG-002 | C7: Utility Relocations | D7: Package Code = PK-102; WBS Code = 1.1 | E7: R1564-v2 | F7: 1.1 Guideway and Civil | G7: ONE_TO_ONE | H7: RETAINED | I7: Carried forward | J7: Source assignment -- not individually reviewed | N7: 10 EVIDENCE & DECISIONS
A8: Commercial Package Register | B8: PKG-003 | C8: Road & Drainage | D8: Package Code = PK-103; WBS Code = 1.1 | E8: R1565-v2 | F8: 1.1 Guideway and Civil | G8: ONE_TO_ONE | H8: RETAINED | I8: Carried forward | J8: Source assignment -- not individually reviewed | N8: 10 EVIDENCE & DECISIONS
A9: Commercial Package Register | B9: PKG-004 | C9: Track Support Works | D9: Package Code = PK-104; WBS Code = 1.1 | E9: R1566-v2 | F9: 1.1 Guideway and Civil | G9: ONE_TO_ONE | H9: RETAINED | I9: Carried forward | J9: Source assignment -- not individually reviewed | N9: 10 EVIDENCE & DECISIONS
A10: Commercial Package Register | B10: PKG-006 | C10: Utility Relocations - Lot 2 | D10: Package Code = PK-106; WBS Code = 1.1 | E10: R1568-v2 | F10: 1.1 Guideway and Civil | G10: ONE_TO_ONE | H10: RETAINED | I10: Carried forward | J10: Source assignment -- not individually reviewed | N10: 10 EVIDENCE & DECISIONS
A11: Commercial Package Register | B11: PKG-007 | C11: Road & Drainage - Lot 2 | D11: Package Code = PK-107; WBS Code = 1.1 | E11: R1569-v2 | F11: 1.1 Guideway and Civil | G11: ONE_TO_ONE | H11: RETAINED | I11: Carried forward | J11: Source assignment -- not individually reviewed | N11: 10 EVIDENCE & DECISIONS
A12: Commercial Package Register | B12: PKG-008 | C12: Track Support Works - Lot 2 | D12: Package Code = PK-108; WBS Code = 1.1 | E12: R1570-v2 | F12: 1.1 Guideway and Civil | G12: ONE_TO_ONE | H12: RETAINED | I12: Carried forward | J12: Source assignment -- not individually reviewed | N12: 10 EVIDENCE & DECISIONS
A13: Commercial Package Register | B13: PKG-009 | C13: Guideway Civil Works - Lot 3 | D13: Package Code = PK-109; WBS Code = 1.1 | E13: R1571-v2 | F13: 1.1 Guideway and Civil | G13: ONE_TO_ONE | H13: RETAINED | I13: Carried forward | J13: Source assignment -- not individually reviewed | N13: 10 EVIDENCE & DECISIONS
A14: Commercial Package Register | B14: PKG-010 | C14: Utility Relocations - Lot 3 | D14: Package Code = PK-110; WBS Code = 1.1 | E14: R1572-v2 | F14: 1.1 Guideway and Civil | G14: ONE_TO_ONE | H14: RETAINED | I14: Carried forward | J14: Source assignment -- not individually reviewed | N14: 10 EVIDENCE & DECISIONS
A15: Contractor Programme | B15: SCH-01-001 | C15: West approach: track-slab survey - installation | D15: WBS Code = 1.1.1 | E15: R1-v2 | F15: 1.1.1 Guideway and Civil - Guideway Structures | G15: ONE_TO_ONE | H15: RETAINED | I15: Carried forward | J15: Source assignment -- not individually reviewed | N15: 10 EVIDENCE & DECISIONS
A16: Contractor Programme | B16: SCH-01-002 | C16: Depot lead: temporary traffic staging - inspection | D16: WBS Code = 1.1.1 | E16: R2-v2 | F16: 1.1.1 Guideway and Civil - Guideway Structures | G16: ONE_TO_ONE | H16: RETAINED | I16: Carried forward | J16: Source assignment -- not individually reviewed | N16: 10 EVIDENCE & DECISIONS
A17: Contractor Programme | B17: SCH-01-004 | C17: River crossing: road restoration - release | D17: WBS Code = 1.1.1 | E17: R4-v2 | F17: 1.1.1 Guideway and Civil - Guideway Structures | G17: ONE_TO_ONE | H17: RETAINED | I17: Carried forward | J17: Source assignment -- not individually reviewed | N17: 10 EVIDENCE & DECISIONS
A18: Contractor Programme | B18: SCH-01-007 | C18: Depot lead: drainage tie-in - inspection | D18: WBS Code = 1.1.1 | E18: R7-v2 | F18: 1.1.1 Guideway and Civil - Guideway Structures | G18: ONE_TO_ONE | H18: RETAINED | I18: Carried forward | J18: Source assignment -- not individually reviewed | N18: 10 EVIDENCE & DECISIONS
... A175: Contractor Programme | B175: SCH-01-003 | C175: Interface works near guideway and civil boundary | D175: WBS Code = 1.1.2 | E175: R3-v2 | F175: 1.1.2 Guideway and Civil - Utility & Roadworks | G175: ONE_TO_ONE | H175: RETAINED | I175: Carried forward | J175: Source assignment -- not individually reviewed | N175: 10 EVIDENCE & DECISIONS
A176: Contractor Programme | B176: SCH-01-005 | C176: Central guideway: drilled-shaft installation - field start - relocated to adjacent governed scope | D176: WBS Code = 1.1.2 | E176: R5-v3 | F176: 1.1.2 Guideway and Civil - Utility & Roadworks | G176: ONE_TO_ONE | H176: APPROVED | I176: Changed, re-decided | J176: Professional decision | K176: Maya Chen, Owner Project Controls | N176: 10 EVIDENCE & DECISIONS
A177: Contractor Programme | B177: SCH-01-006 | C177: West approach: retaining-wall excavation - installation | D177: WBS Code = 1.1.2 | E177: R6-v2 | F177: 1.1.2 Guideway and Civil - Utility & Roadworks | G177: ONE_TO_ONE | H177: RETAINED | I177: Carried forward | J177: Source assignment -- not individually reviewed | N177: 10 EVIDENCE & DECISIONS
A178: Contractor Programme | B178: SCH-01-009 | C178: River crossing: track-slab survey - release | D178: WBS Code = 1.1.2 | E178: R9-v2 | F178: 1.1.2 Guideway and Civil - Utility & Roadworks | G178: ONE_TO_ONE | H178: RETAINED | I178: Carried forward | J178: Source assignment -- not individually reviewed | N178: 10 EVIDENCE & DECISIONS
A179: Contractor Programme | B179: SCH-01-012 | C179: Depot lead: road restoration - inspection | D179: WBS Code = 1.1.2 | E179: R12-v2 | F179: 1.1.2 Guideway and Civil - Utility & Roadworks | G179: ONE_TO_ONE | H179: RETAINED | I179: Carried forward | J179: Source assignment -- not individually reviewed | N179: 10 EVIDENCE & DECISIONS
A180: Contractor Programme | B180: SCH-01-015 | C180: Central guideway: drainage tie-in - field start | D180: WBS Code = 1.1.2 | E180: R15-v2 | F180: 1.1.2 Guideway and Civil - Utility & Roadworks | G180: ONE_TO_ONE | H180: RETAINED | I180: Carried forward | J180: Source assignment -- not individually reviewed | N180: 10 EVIDENCE & DECISIONS
A181: Contractor Programme | B181: SCH-01-018 | C181: East portal: temporary traffic staging - turnover | D181: WBS Code = 1.1.2 | E181: R18-v2 | F181: 1.1.2 Guideway and Civil - Utility & Roadworks | G181: ONE_TO_ONE | H181: RETAINED | I181: Carried forward | J181: Source assignment -- not individually reviewed | N181: 10 EVIDENCE & DECISIONS
A182: Contractor Programme | B182: SCH-01-021 | C182: West approach: drilled-shaft installation - installation | D182: WBS Code = 1.1.2 | E182: R21-v2 | F182: 1.1.2 Guideway and Civil - Utility & Roadworks | G182: ONE_TO_ONE | H182: RETAINED | I182: Carried forward | J182: Source assignment -- not individually reviewed | N182: 10 EVIDENCE & DECISIONS
A183: Contractor Programme | B183: SCH-01-024 | C183: River crossing: utility relocation - release | D183: WBS Code = 1.1.2 | E183: R24-v2 | F183: 1.1.2 Guideway and Civil - Utility & Roadworks | G183: ONE_TO_ONE | H183: RETAINED | I183: Carried forward | J183: Source assignment -- not individually reviewed | N183: 10 EVIDENCE & DECISIONS
A184: Contractor Programme | B184: SCH-01-027 | C184: Depot lead: guideway pier reinforcement - inspection | D184: WBS Code = 1.1.2 | E184: R27-v2 | F184: 1.1.2 Guideway and Civil - Utility & Roadworks | G184: ONE_TO_ONE | H184: RETAINED | I184: Carried forward | J184: Source assignment -- not individually reviewed | N184: 10 EVIDENCE & DECISIONS
A185: Contractor Programme | B185: SCH-01-030 | C185: Central guideway: retaining-wall excavation - field start | D185: WBS Code = 1.1.2 | E185: R30-v2 | F185: 1.1.2 Guideway and Civil - Utility & Roadworks | G185: ONE_TO_ONE | H185: RETAINED | I185: Carried forward | J185: Source assignment -- not individually reviewed | N185: 10 EVIDENCE & DECISIONS
A186: Contractor Programme | B186: SCH-01-033 | C186: East portal: track-slab survey - turnover | D186: WBS Code = 1.1.2 | E186: R33-v2 | F186: 1.1.2 Guideway and Civil - Utility & Roadworks | G186: ONE_TO_ONE | H186: RETAINED | I186: Carried forward | J186: Source assignment -- not individually reviewed | N186: 10 EVIDENCE & DECISIONS
A187: Contractor Programme | B187: SCH-01-036 | C187: West approach: road restoration - installation | D187: WBS Code = 1.1.2 | E187: R36-v2 | F187: 1.1.2 Guideway and Civil - Utility & Roadworks | G187: ONE_TO_ONE | H187: RETAINED | I187: Carried forward | J187: Source assignment -- not individually reviewed | N187: 10 EVIDENCE & DECISIONS
A188: Contractor Programme | B188: SCH-01-039 | C188: River crossing: drainage tie-in - release | D188: WBS Code = 1.1.2 | E188: R39-v2 | F188: 1.1.2 Guideway and Civil - Utility & Roadworks | G188: ONE_TO_ONE | H188: RETAINED | I188: Carried forward | J188: Source assignment -- not individually reviewed | N188: 10 EVIDENCE & DECISIONS
... A237: Cost & Forecast Control Accounts | B237: CST-01-004 | C237: Guideway and Civil - roadworks - field package | D237: Cost Account = CA-1004; WBS Code = 1.1.2 | E237: R1086-v2 | F237: 1.1.2 Guideway and Civil - Utility & Roadworks | G237: ONE_TO_ONE | H237: RETAINED | I237: Carried forward | J237: Source assignment -- not individually reviewed | N237: 10 EVIDENCE & DECISIONS
A238: Cost & Forecast Control Accounts | B238: CST-01-005 | C238: Guideway and Civil - temporary works - supply and install - relocated to adjacent governed scope | D238: Cost Account = CA-1005; WBS Code = 1.1.2 | E238: R1087-v3 | F238: 1.1.2 Guideway and Civil - Utility & Roadworks | G238: ONE_TO_ONE | H238: APPROVED | I238: Changed, re-decided | J238: Professional decision | K238: Maya Chen, Owner Project Controls | N238: 10 EVIDENCE & DECISIONS
A239: Cost & Forecast Control Accounts | B239: CST-01-006 | C239: Guideway and Civil - concrete structures - professional services | D239: Cost Account = CA-1006; WBS Code = 1.1.2 | E239: R1088-v2 | F239: 1.1.2 Guideway and Civil - Utility & Roadworks | G239: ONE_TO_ONE | H239: RETAINED | I239: Carried forward | J239: Source assignment -- not individually reviewed | N239: 10 EVIDENCE & DECISIONS
A240: Cost & Forecast Control Accounts | B240: CST-01-008 | C240: Guideway and Civil - temporary works - closeout | D240: Cost Account = CA-1008; WBS Code = 1.1.2 | E240: R1090-v2 | F240: 1.1.2 Guideway and Civil - Utility & Roadworks | G240: ONE_TO_ONE | H240: RETAINED | I240: Carried forward | J240: Source assignment -- not individually reviewed | N240: 10 EVIDENCE & DECISIONS
A241: Cost & Forecast Control Accounts | B241: CST-01-010 | C241: Guideway and Civil - roadworks - supply and install | D241: Cost Account = CA-1010; WBS Code = 1.1.2 | E241: R1092-v2 | F241: 1.1.2 Guideway and Civil - Utility & Roadworks | G241: ONE_TO_ONE | H241: RETAINED | I241: Carried forward | J241: Source assignment -- not individually reviewed | N241: 10 EVIDENCE & DECISIONS
A242: Cost & Forecast Control Accounts | B242: CST-01-012 | C242: Guideway and Civil - concrete structures - allowance | D242: Cost Account = CA-1012; WBS Code = 1.1.2 | E242: R1094-v2 | F242: 1.1.2 Guideway and Civil - Utility & Roadworks | G242: ONE_TO_ONE | H242: RETAINED | I242: Carried forward | J242: Source assignment -- not individually reviewed | N242: 10 EVIDENCE & DECISIONS
A243: Cost & Forecast Control Accounts | B243: CST-01-014 | C243: Guideway and Civil - temporary works - field package | D243: Cost Account = CA-1014; WBS Code = 1.1.2 | E243: R1096-v2 | F243: 1.1.2 Guideway and Civil - Utility & Roadworks | G243: ONE_TO_ONE | H243: RETAINED | I243: Carried forward | J243: Source assignment -- not individually reviewed | N243: 10 EVIDENCE & DECISIONS
A244: Cost & Forecast Control Accounts | B244: CST-01-016 | C244: Guideway and Civil - roadworks - professional services | D244: Cost Account = CA-1016; WBS Code = 1.1.2 | E244: R1098-v2 | F244: 1.1.2 Guideway and Civil - Utility & Roadworks | G244: ONE_TO_ONE | H244: RETAINED | I244: Carried forward | J244: Source assignment -- not individually reviewed | N244: 10 EVIDENCE & DECISIONS
A245: Cost & Forecast Control Accounts | B245: CST-01-018 | C245: Guideway and Civil - concrete structures - closeout | D245: Cost Account = CA-1018; WBS Code = 1.1.2 | E245: R1100-v2 | F245: 1.1.2 Guideway and Civil - Utility & Roadworks | G245: ONE_TO_ONE | H245: RETAINED | I245: Carried forward | J245: Source assignment -- not individually reviewed | N245: 10 EVIDENCE & DECISIONS
...

Sheet 09 WBS EXPLORER
A1: WBS EXPLORER
A2: The approved WBS as integration spine, with governed relationship populations beneath it.
A3: Executive | B3: Issues | C3: Integration | D3: Project | E3: Changes | F3: Crosswalk | G3: Evidence | H3: Sources
A4: Governed relationship coverage/status → advanced approved scope / relationship-row view
A5: WBS | B5: Element | C5: Level | D5: Schedule | E5: Cost / forecast | F5: Package / contract | G5: Other | H5: Open / unresolved | I5: Changed | J5: Integration condition | K5: Crosswalk
B6: HarbourLink Urban Transit Expansion | C6: 0 | D6: 899 governed relationships | E6: 399 governed relationships | F6: 59 governed relationships | G6: 0 governed relationships | H6: 0 | I6: 7 | J6: Aligned: Schedule and cost both relate through this WBS branch. 59 package/contract relationships also project through this branch. | K6: 08 CROSSWALK
A7: 1 | B7: HarbourLink Urban Transit Expansion | C7: 1 | D7: 899 governed relationships | E7: 399 governed relationships | F7: 59 governed relationships | G7: 0 governed relationships | H7: 0 | I7: 7 | J7: Aligned: Schedule and cost both relate through this WBS branch. 59 package/contract relationships also project through this branch. | K7: 08 CROSSWALK
A8: 1.1 | B8: Guideway and Civil | C8: 2 | D8: 181 governed relationships | E8: 81 governed relationships | F8: 9 governed relationships | G8: 0 governed relationships | H8: 0 | I8: 5 | J8: Aligned: Schedule and cost both relate through this WBS branch. 9 package/contract relationships also project through this branch. | K8: 08 CROSSWALK
A9: 1.1.1 | B9: Guideway and Civil - Guideway Structures | C9: 3 | D9: 120 governed relationships | E9: 40 governed relationships | F9: 0 governed relationships | G9: 0 governed relationships | H9: 0 | I9: 3 | J9: Aligned: Schedule and cost both relate through this WBS branch. | K9: 08 CROSSWALK
A10: 1.1.1.1 | B10: Guideway Structures - East Segment | C10: 4 | D10: 0 governed relationships | E10: 0 governed relationships | F10: 0 governed relationships | G10: 0 governed relationships | H10: 0 | I10: 0 | J10: Partial: No governed schedule or cost relationships in this WBS branch. | K10: 08 CROSSWALK
A11: 1.1.1.2 | B11: Guideway Structures - West Segment | C11: 4 | D11: 0 governed relationships | E11: 0 governed relationships | F11: 0 governed relationships | G11: 0 governed relationships | H11: 0 | I11: 0 | J11: Partial: No governed schedule or cost relationships in this WBS branch. | K11: 08 CROSSWALK
A12: 1.1.2 | B12: Guideway and Civil - Utility & Roadworks | C12: 3 | D12: 61 governed relationships | E12: 41 governed relationships | F12: 0 governed relationships | G12: 0 governed relationships | H12: 0 | I12: 2 | J12: Aligned: Schedule and cost both relate through this WBS branch. | K12: 08 CROSSWALK
A13: 1.1.2.1 | B13: Utility & Roadworks - East Segment | C13: 4 | D13: 0 governed relationships | E13: 0 governed relationships | F13: 0 governed relationships | G13: 0 governed relationships | H13: 0 | I13: 0 | J13: Partial: No governed schedule or cost relationships in this WBS branch. | K13: 08 CROSSWALK
A14: 1.1.2.2 | B14: Utility & Roadworks - West Segment | C14: 4 | D14: 0 governed relationships | E14: 0 governed relationships | F14: 0 governed relationships | G14: 0 governed relationships | H14: 0 | I14: 0 | J14: Partial: No governed schedule or cost relationships in this WBS branch. | K14: 08 CROSSWALK
A15: 1.1.3 | B15: Guideway and Civil - Track Support Works | C15: 3 | D15: 0 governed relationships | E15: 0 governed relationships | F15: 0 governed relationships | G15: 0 governed relationships | H15: 0 | I15: 0 | J15: Partial: No governed schedule or cost relationships in this WBS branch. | K15: 08 CROSSWALK
A16: 1.1.3.1 | B16: Track Support Works - East Segment | C16: 4 | D16: 0 governed relationships | E16: 0 governed relationships | F16: 0 governed relationships | G16: 0 governed relationships | H16: 0 | I16: 0 | J16: Partial: No governed schedule or cost relationships in this WBS branch. | K16: 08 CROSSWALK
A17: 1.1.3.2 | B17: Track Support Works - West Segment | C17: 4 | D17: 0 governed relationships | E17: 0 governed relationships | F17: 0 governed relationships | G17: 0 governed relationships | H17: 0 | I17: 0 | J17: Partial: No governed schedule or cost relationships in this WBS branch. | K17: 08 CROSSWALK
A18: 1.1.4 | B18: Guideway and Civil - Civil Interfaces | C18: 3 | D18: 0 governed relationships | E18: 0 governed relationships | F18: 0 governed relationships | G18: 0 governed relationships | H18: 0 | I18: 0 | J18: Partial: No governed schedule or cost relationships in this WBS branch. | K18: 08 CROSSWALK
... A85: 1.6.4.2 | B85: Delivery Integration - Delivery Partners | C85: 4 | D85: 0 governed relationships | E85: 0 governed relationships | F85: 0 governed relationships | G85: 0 governed relationships | H85: 0 | I85: 0 | J85: Partial: No governed schedule or cost relationships in this WBS branch. | K85: 08 CROSSWALK

Sheet 10 EVIDENCE & DECISIONS
A1: EVIDENCE & DECISIONS
A2: Source says → relationship / interpretation → professional decision → current governed state.
A3: Executive | B3: Issues | C3: Integration | D3: Project | E3: Changes | F3: Crosswalk | G3: Evidence | H3: Sources
A5: Relationship | B5: Source / record | C5: SOURCE SAYS | D5: RELATIONSHIP / INTERPRETATION | E5: Contrary / competing evidence | F5: PROFESSIONAL DECISION | G5: Decision scope | H5: CURRENT GOVERNED STATE | I5: Change / reopen | J5: Crosswalk
A6: R1563-v3 | B6: Commercial Package Register / PKG-001 | C6: Package Code = PK-101; WBS Code = 1.1;1.2 | D6: Proposed by Professional; target 1.1 Guideway and Civil | E6: Source states 'WBS Code' = '1.1;1.2' -- names no element of this WBS -- professional reason (Maya Chen, Owner Project Controls): Source package register explicitly states both Owner-WBS branches. | F6: Maya Chen, Owner Project Controls: Earlier professional decision, carried forward | G6: Individual, carried forward | H6: RETAINED / ONE_TO_MANY; | I6: Carried forward | J6: 08 CROSSWALK
A7: R1564-v2 | B7: Commercial Package Register / PKG-002 | C7: Package Code = PK-102; WBS Code = 1.1 | D7: Proposed by Source assignment; target 1.1 Guideway and Civil | E7: None recorded | F7: No individual professional decision recorded; Source assignment -- not individually reviewed | G7: Not individually decided | H7: RETAINED / ONE_TO_ONE; | I7: Carried forward | J7: 08 CROSSWALK
A8: R1565-v2 | B8: Commercial Package Register / PKG-003 | C8: Package Code = PK-103; WBS Code = 1.1 | D8: Proposed by Source assignment; target 1.1 Guideway and Civil | E8: None recorded | F8: No individual professional decision recorded; Source assignment -- not individually reviewed | G8: Not individually decided | H8: RETAINED / ONE_TO_ONE; | I8: Carried forward | J8: 08 CROSSWALK
A9: R1566-v2 | B9: Commercial Package Register / PKG-004 | C9: Package Code = PK-104; WBS Code = 1.1 | D9: Proposed by Source assignment; target 1.1 Guideway and Civil | E9: None recorded | F9: No individual professional decision recorded; Source assignment -- not individually reviewed | G9: Not individually decided | H9: RETAINED / ONE_TO_ONE; | I9: Carried forward | J9: 08 CROSSWALK
A10: R1568-v2 | B10: Commercial Package Register / PKG-006 | C10: Package Code = PK-106; WBS Code = 1.1 | D10: Proposed by Source assignment; target 1.1 Guideway and Civil | E10: None recorded | F10: No individual professional decision recorded; Source assignment -- not individually reviewed | G10: Not individually decided | H10: RETAINED / ONE_TO_ONE; | I10: Carried forward | J10: 08 CROSSWALK
A11: R1569-v2 | B11: Commercial Package Register / PKG-007 | C11: Package Code = PK-107; WBS Code = 1.1 | D11: Proposed by Source assignment; target 1.1 Guideway and Civil | E11: None recorded | F11: No individual professional decision recorded; Source assignment -- not individually reviewed | G11: Not individually decided | H11: RETAINED / ONE_TO_ONE; | I11: Carried forward | J11: 08 CROSSWALK
A12: R1570-v2 | B12: Commercial Package Register / PKG-008 | C12: Package Code = PK-108; WBS Code = 1.1 | D12: Proposed by Source assignment; target 1.1 Guideway and Civil | E12: None recorded | F12: No individual professional decision recorded; Source assignment -- not individually reviewed | G12: Not individually decided | H12: RETAINED / ONE_TO_ONE; | I12: Carried forward | J12: 08 CROSSWALK
A13: R1571-v2 | B13: Commercial Package Register / PKG-009 | C13: Package Code = PK-109; WBS Code = 1.1 | D13: Proposed by Source assignment; target 1.1 Guideway and Civil | E13: None recorded | F13: No individual professional decision recorded; Source assignment -- not individually reviewed | G13: Not individually decided | H13: RETAINED / ONE_TO_ONE; | I13: Carried forward | J13: 08 CROSSWALK
A14: R1572-v2 | B14: Commercial Package Register / PKG-010 | C14: Package Code = PK-110; WBS Code = 1.1 | D14: Proposed by Source assignment; target 1.1 Guideway and Civil | E14: None recorded | F14: No individual professional decision recorded; Source assignment -- not individually reviewed | G14: Not individually decided | H14: RETAINED / ONE_TO_ONE; | I14: Carried forward | J14: 08 CROSSWALK
A15: R1-v2 | B15: Contractor Programme / SCH-01-001 | C15: WBS Code = 1.1.1 | D15: Proposed by Source assignment; target 1.1.1 Guideway and Civil - Guideway Structures | E15: None recorded | F15: No individual professional decision recorded; Source assignment -- not individually reviewed | G15: Not individually decided | H15: RETAINED / ONE_TO_ONE; | I15: Carried forward | J15: 08 CROSSWALK
A16: R2-v2 | B16: Contractor Programme / SCH-01-002 | C16: WBS Code = 1.1.1 | D16: Proposed by Source assignment; target 1.1.1 Guideway and Civil - Guideway Structures | E16: None recorded | F16: No individual professional decision recorded; Source assignment -- not individually reviewed | G16: Not individually decided | H16: RETAINED / ONE_TO_ONE; | I16: Carried forward | J16: 08 CROSSWALK
... A1631: R1081-v3 | B1631: Contractor Programme / SCH-90-901 | C1631: No explicit source assertion recorded | D1631: Proposed by Professional; target NEW_SCOPE | E1631: None recorded | F1631: No individual professional decision recorded; Retired -- no longer reported | G1631: Earlier decision, carried forward | H1631: RETIRED / NEW_SCOPE; | I1631: Retired | J1631: 08 CROSSWALK

Sheet 11 SOURCES & PROVENANCE
A1: SOURCES & PROVENANCE
A2: The information boundary of this workbook. Supplied evidence is not the same as established interpretation.
A3: Executive | B3: Issues | C3: Integration | D3: Project | E3: Changes | F3: Crosswalk | G3: Evidence | H3: Sources
A5: Project source-representation integrity | B5: Established
A7: Source | B7: Governed role | C7: Revision | D7: Reporting period | E7: Rows | F7: Role basis | G7: Role validity | H7: Table boundary | I7: Interpretation | J7: Interpretation basis | K7: Format | L7: File integrity
A8: Commercial Package Register | B8: WORK_PACKAGE_LIST | C8: Rev 1 | D8: Commercial Package Register Cycle 2 | E8: 60 | F8: declared at upload | G8: RETAINED | H8: ESTABLISHED | I8: TABLE | J8: SOURCE_NATIVE_SCHEMA | K8: xlsx | L8: SOURCE_REPRESENTATION_ESTABLISHED
A9: Contractor Programme | B9: SCHEDULE | C9: Rev 1 | D9: Contractor Programme Cycle 2 | E9: 1082 | F9: declared at upload | G9: RETAINED | H9: ESTABLISHED | I9: TABLE | J9: DETERMINISTIC_SEMANTIC_RELATION | K9: csv | L9: SOURCE_REPRESENTATION_ESTABLISHED
A10: Cost & Forecast Control Accounts | B10: COST_ESTIMATE | C10: Rev 1 | D10: Cost & Forecast Control Accounts Cycle 2 | E10: 480 | F10: declared at upload | G10: RETAINED | H10: ESTABLISHED | I10: TABLE | J10: DETERMINISTIC_SEMANTIC_RELATION | K10: xlsx | L10: SOURCE_REPRESENTATION_ESTABLISHED
A11: Owner WBS | B11: WBS_DICTIONARY | C11: Rev 0 | D11: Initial | E11: 79 | F11: declared at upload | G11: AS_SUPPLIED | H11: ESTABLISHED | I11: TABLE | J11: DETERMINISTIC_SEMANTIC_RELATION | K11: xlsx | L11: SOURCE_REPRESENTATION_ESTABLISHED

Sheet 12 ASSURANCE
A1: ASSURANCE
A2: Exact governance detail and output boundaries. This sheet supports review; it does not create authority.
A3: Executive | B3: Issues | C3: Integration | D3: Project | E3: Changes | F3: Crosswalk | G3: Evidence | H3: Sources
A5: Assurance item | B5: Recorded value
A6: Output version | B6: Premium Workbook Rev 2
A7: Project | B7: HarbourLink Urban Transit Expansion
A8: Approved mapping version | B8: MV-2 (REPORTING)
A9: Approved by | B9: Maya Chen, Owner Project Controls
A10: Approved timestamp | B10: 2026-10-16 14:14 UTC
A11: WBS version | B11: 1
A12: Source-representation integrity | B12: SOURCE_REPRESENTATION_ESTABLISHED
A13: Source-integrity unresolved count | B13: 0
A14: Relationship rows | B14: 1626
A15: Generation timestamp | B15: 2026-10-16 14:16 UTC
A17: Interpretation boundary
A18: Workbook/App/JSON/PDF agreement can prove that outputs consume one governed state. It cannot prove that an upstream source interpretation is true. Source representation integrity is a separate prerequisite for substantive management claims.
A21: Known output limitations
A22: • Management amount/date/duration measures are withheld unless field semantics are explicitly governed for that use.
A23: • The workbook projects independent source structures through governed WBS relationships; it does not create direct source-to-source truth.
A24: • Sheet 04 (issues for review) is not a ranked list and does not claim objective materiality without a governed ranking basis.
A25: • Fictional evaluation case. No real-client provenance, privacy/security/compliance or hosting-residency claim is made by this workbook.
A27: Visual / metric ledger
A28: ID | B28: Title | C28: Management question | D28: Basis / population | E28: Unresolved treatment | F28: Transformation | G28: Drill path | H28: Records | I28: Status
A29: V1 | B29: WBS × control-view integration matrix | C29: Which supplied project-control views have governed relationships through each major Owner-WBS branch? | D29: Latest approved MappingVersion and its approved source-role basis. | Non-retired governed/open relationship population scoped through each displayed WBS branch. | E29: Unresolved is distinct from assessed zero coverage and source-not-supplied. | F29: Categorical state from supplied source role plus branch-scoped governed/open relationships; no health percentage. | G29: visual → WBS branch → integrated project → Crosswalk → evidence/professional decision | H29: 1357 | I29: AVAILABLE
A30: V2 | B30: Management-attention concentration by WBS branch | C30: Where are governed reopened, unresolved or contradictory relationship populations concentrated? | D30: Latest approved relationship state and retained relationship evidence. | Branch-scoped relationships with reopened/unresolved/contradictory evidence. | E30: Counts remain explicit; no record-count-to-materiality inference. | F30: Count qualifying relationship records by approved WBS branch; overlapping categories remain separately labelled. | G30: visual → WBS branch → Changes/What Matters Now → Crosswalk → evidence | H30: 6 | I30: AVAILABLE
A31: V3 | B31: Cycle governed-state composition | C31: How much relationship state carried forward versus required revalidation/redecision/new/retired treatment? | D31: Current approved MappingVersion change labels relative to prior approved state. | One current/historical change label per governed relationship version represented in output. | E31: Unresolved relationship outcome remains separate from change-state composition. | F31: Count governed relationships by the existing change labels; no speed/value claim inferred. | G31: visual → change class → Changes & Revalidation → relationship → evidence | H31: 1625 | I31: AVAILABLE
A32: V4 | B32: Governed cost / forecast view | C32: What governed cost/forecast amount can be shown by WBS scope? | D32: No sufficient quantitative contract supplied. | None admitted. | E32: All amount claims withheld. | F32: No aggregation performed. | G32: See Sources & Provenance / Assurance for withholding reason. | H32: 0 | I32: WITHHELD

Sheet 13 REVISIONS & PERIODS
A1: REVISIONS & PERIODS
A2: Which reporting revision this workbook is built on, what superseded what, and why only part of the governed relationship state reopened.
A3: Executive | B3: Issues | C3: Integration | D3: Project | E3: Changes | F3: Crosswalk | G3: Evidence | H3: Sources
A5: State of record | B5: MV-2 approved by Maya Chen, Owner Project Controls · 2026-10-16 14:14 UTC
A6: Built on these revisions | B6: Owner WBS (Initial Rev 0); Contractor Programme (Contractor Programme Cycle 2 Rev 1); Cost & Forecast Control Accounts (Cost & Forecast Control Accounts Cycle 2 Rev 1); Commercial Package Register (Commercial Package Register Cycle 2 Rev 1)
A8: Selective revalidation in this version
A9: Relationships (unique) by change since the previous approved version -- the same composition as 07 CHANGES & REVALIDATION. Carried forward work was not rebuilt.
A10: Relationships in this version | B10: 1625
A11: Carried forward without rework | B11: 1614
A12: Came back and were decided again (changed) | B12: 4
A13: New in this version | B13: 4
A14: Retired (no longer reported) | B14: 3
